Workbook

Sheet Dashboard
B2: Legal Dashboard (LD) – Monthly Report
B4: Source file: query_LD Monthly_report_Mar 26 ver.2.xlsx | Template structure reference: TLS8001_Legal_Compliance_Dashboard_March Ver2.0_13032026.xlsx
B6: Total Legal Requirements | E6: Active Laws | H6: Implemented | K6: Active Pending
B7: =Summary_KPI!B3 -> 74 | E7: =Summary_KPI!B4 -> 71 | H7: =Summary_KPI!B5 -> 69 | K7: =Summary_KPI!B11 -> 3
B9: Implemented % | E9: Top Exposure Category | I9: Data Quality Watch Blank Date = 1 | Future Date = 3 | Missing Ref. No. = 51
B10: =Summary_KPI!B12 -> 0.93243243 | E10: =Summary_KPI!B13 -> กฎหมายคุ้มครองแรงงาน
B12: Executive Highlights • Total 74 รายการ | Active 71 (95.9%) | Inactive 3 • Implemented 69 (93.2%) | Evaluated 4 | Under Review 1 • Active Pending 3 รายการ ต้องเร่งติดตามเชิงปฏิบัติการ • Top exposure = กฎหมายคุ้มครองแรงงาน (28 รายการ) • Future monitoring 3 รายการ | Blank Date 1 รายการ • รอบนี้ยังไม่มีฐานเปรียบเทียบเดือนก่อนหน้าในไฟล์ต้นทาง | H12: Data Notes / Recommendations • ใช้ Compliance Implementation Status และ Legal Validity Status เป็น KPI หลัก • รายการ Active แต่ยังไม่ Implemented ให้จัดเป็น priority follow-up • แยก Inactive ออกจาก active action plan และจัด archive logic ให้ชัดเจน • เพิ่ม field Owner / Due Date / Evidence Log เพื่อยกระดับ dashboard รายเดือน • รายการ future date ควรแยกเป็น upcoming legal monitoring
B21: Top Action Backlog / Priority Review | G21: คำอธิบายรายงาน: เดือนมีนาคม 2569 รายงานฉบับนี้จัดทำในรูปแบบ Professional Legal Dashboard – Modern Executive โดยใช้โครงสร้าง dashboard จากไฟล์ตัวอย่างและอัปเดตข้อมูลจริงจาก Legal Compliance Management System เพื่อใช้ติดตามจำนวนข้อกำหนดทั้งหมด สถานะการดำเนินการ ความพร้อมเชิง compliance หมวดกฎหมายที่มี exposure สูง ประเด็น backlog และ data quality observation สำหรับการทบทวนรายเดือนของผู้บริหารและผู้เกี่ยวข้อง ทั้งนี้รอบปัจจุบันยังไม่มีข้อมูล month-on-month baseline จึงสรุปในลักษณะ current month snapshot
B22: Law / Requirement | C22: Category | D22: Status | E22: Validity
B23: =Action_Backlog!B3 -> พระราชกฤษฎีกา กำหนดระยะเวลาเริ่มดำเนินการจัดเก็บเงินสะสมและเงินสมทบกองทุนสงเคราะห์ลูกจ้าง พ.ศ. 2567 | C23: =Action_Backlog!C3 -> กฎหมายคุ้มครองแรงงาน | D23: =Action_Backlog!D3 -> Evaluated | E23: =Action_Backlog!E3 -> Active
B24: =Action_Backlog!B4 -> กฎกระทรวง กำหนดค่าล่วงเวลาและค่าตอบแทนการทำงานที่เกินวันละแปดชั่วโมง ในงานเฝ้าดูแลสถานที่หรือทรัพย์สินอันเป็นหน้าที่การทำงานปกติของลูกจ้าง พ.ศ. 2568 | C24: =Action_Backlog!C4 -> กฎหมายคุ้มครองแรงงาน | D24: =Action_Backlog!D4 -> Evaluated | E24: =Action_Backlog!E4 -> Active
B25: =Action_Backlog!B5 -> กฎกระทรวง กำหนดประเภทของสถานประกอบกิจการและการดำเนินการของสถานประกอบกิจการในการป้องกันและแก้ไขปัญหาการตั้งครรภ์ในวัยรุ่นแก่ลูกจ้างซึ่งเป็นวัยรุ่น พ.ศ. 2561 | C25: =Action_Backlog!C5 -> กฎหมาย อื่น ๆ | D25: =Action_Backlog!D5 -> Evaluated | E25: =Action_Backlog!E5 -> Active
B26: =Action_Backlog!B6 -> กฎกระทรวง กำหนดหลักเกณฑ์และวิธีการจัดการสงเคราะห์แก่ลูกจ้าง ในกรณีที่ลูกจ้างออกจากงานหรือตาย พ.ศ. 2567 | C26: =Action_Backlog!C6 -> กฎหมายคุ้มครองแรงงาน | D26: =Action_Backlog!D6 -> Implemented | E26: =Action_Backlog!E6 -> Inactive
B27: =Action_Backlog!B7 -> กฎกระทรวง กำหนดอัตราเงินสะสมและเงินสมทบกองทุนสงเคราะห์ลูกจ้าง พ.ศ. 2567 | C27: =Action_Backlog!C7 -> กฎหมายคุ้มครองแรงงาน | D27: =Action_Backlog!D7 -> Evaluated | E27: =Action_Backlog!E7 -> Inactive

Sheet กฎหมายใหม่ล่าสุด
A1: กฎหมายใหม่ล่าสุด
A2: เกณฑ์การคัดเลือก: เลือกเฉพาะรายการที่มีวันที่ล่าสุดที่สุดในข้อมูล = 01/12/2026
A3: จำนวนรายการ | B3: =COUNTA($B$6:$B$1048576) -> 1 | C3: คัดจากคอลัมน์ Date of Issue / Effective Date
A5: Subject | B5: No | C5: Category | D5: Document ID / Reference No. | E5: Legal / Regulatory Title | F5: Date of Issue / Effective Date | G5: Legal Reference Link | H5: Key Legal & Regulatory Requirements | I5: Compliance Implementation Status | J5: (Y) Compliant / (N) Non-Compliant | K5: Implementation Guidance & Evidence Examples | L5: Legal Validity Status | M5: Approval status
A6: ประกาศคณะกรรมการการแพทย์ตามพระราชบัญญัติประกันสังคม | B6: 57 | C6: กฎหมายประกันสังคม | D6: 102381 | E6: ประกาศคณะกรรมการการแพทย์ตามพระราชบัญญัติประกันสังคม เรื่อง หลักเกณฑ์และอัตราค่าบริการทางการแพทย์เพื่อเพิ่มประสิทธิภาพการเข้าถึงการรักษาของผู้ประกันตนในระบบประกันสังคม | F6: 46357 | G6: https://ratchakitcha.soc.go.th/documents/102381.pdf | H6: ประกาศฉบับนี้เป็นกฎหมายที่กำหนด หลักเกณฑ์และอัตราค่าบริการทางการแพทย์เพิ่มเติมเป็นการเฉพาะ เพื่อสนับสนุนการรักษาผู้ประกันตนใน 2 กลุ่มโรคสำคัญ คือ 1) โรคหลอดเลือดสมองอุดตัน โดยเฉพาะหัตถการ Thrombectomy 2) โรคหัวใจและหลอดเลือด โดยเฉพาะการสวนหัวใจ การขยายหลอดเลือดหัวใจ และหัตถการหัวใจเฉพาะทางอื่น ๆ | I6: Implemented | J6: จริง | K6: 1) ทบทวน ทะเบียนกฎหมายและข้อกำหนดที่เกี่ยวข้อง ให้ครอบคลุมประกาศนี้ โดยเฉพาะในส่วนสิทธิประโยชน์ด้านการรักษาพยาบาลของผู้ประกันตน 2) สื่อสารให้ HR, welfare, พยาบาลวิชาชีพ, เจ้าหน้าที่ประกันสังคม และลูกจ้างทราบว่า ผู้ประกันตนสามารถเข้าถึงการรักษาภาวะฉุกเฉินบางประเภทได้ภายใต้หลักเกณฑ์ใหม่ของประกันสังคม 3) ใช้เป็นข้อมูลสนับสนุนด้าน employee well-being และ labour welfare โดยเฉพาะในองค์กรที่มีลูกจ้างกลุ่มเสี่ยงโรคหัวใจ โรคหลอดเลือดสมอง หรือโรคไม่ติดต่อเรื้อรังจำนวนมาก 4) บูรณาการเข้ากับระบบ มรท.8001 ในด้าน การอบรม/การสื่อสารสิทธิ, การจัดการสวัสดิการ, และ การดูแลแรงงานหลังเจ็บป่วยหรือกลับเข้าทำงาน เพื่อช่วยให้แรงงานเข้าถึงสิทธิได้รวดเร็วขึ้น 5) ในการตรวจติดตามภายใน องค์กรอาจตรวจว่ามีการสื่อสารสิทธิประโยชน์ประกันสังคมที่สำคัญแก่ลูกจ้างอย่างทั่วถึงหรือไม่ โดยเฉพาะกรณีโรครุนแรงที่ต้องรักษาเร่งด่วน | L6: Active | M6: 3

Sheet กฎหมายประจำเดือน
A1: กฎหมายประจำเดือน
A2: เกณฑ์การคัดเลือก: เลือกเฉพาะรายการในเดือนล่าสุดที่สุดของข้อมูล = 12/2026
A3: จำนวนรายการ | B3: =COUNTA($B$6:$B$1048576) -> 1 | C3: คัดจากคอลัมน์ Date of Issue / Effective Date
A5: Subject | B5: No | C5: Category | D5: Document ID / Reference No. | E5: Legal / Regulatory Title | F5: Date of Issue / Effective Date | G5: Legal Reference Link | H5: Key Legal & Regulatory Requirements | I5: Compliance Implementation Status | J5: (Y) Compliant / (N) Non-Compliant | K5: Implementation Guidance & Evidence Examples | L5: Legal Validity Status | M5: Approval status
A6: ประกาศคณะกรรมการการแพทย์ตามพระราชบัญญัติประกันสังคม | B6: 57 | C6: กฎหมายประกันสังคม | D6: 102381 | E6: ประกาศคณะกรรมการการแพทย์ตามพระราชบัญญัติประกันสังคม เรื่อง หลักเกณฑ์และอัตราค่าบริการทางการแพทย์เพื่อเพิ่มประสิทธิภาพการเข้าถึงการรักษาของผู้ประกันตนในระบบประกันสังคม | F6: 46357 | G6: https://ratchakitcha.soc.go.th/documents/102381.pdf | H6: ประกาศฉบับนี้เป็นกฎหมายที่กำหนด หลักเกณฑ์และอัตราค่าบริการทางการแพทย์เพิ่มเติมเป็นการเฉพาะ เพื่อสนับสนุนการรักษาผู้ประกันตนใน 2 กลุ่มโรคสำคัญ คือ 1) โรคหลอดเลือดสมองอุดตัน โดยเฉพาะหัตถการ Thrombectomy 2) โรคหัวใจและหลอดเลือด โดยเฉพาะการสวนหัวใจ การขยายหลอดเลือดหัวใจ และหัตถการหัวใจเฉพาะทางอื่น ๆ | I6: Implemented | J6: จริง | K6: 1) ทบทวน ทะเบียนกฎหมายและข้อกำหนดที่เกี่ยวข้อง ให้ครอบคลุมประกาศนี้ โดยเฉพาะในส่วนสิทธิประโยชน์ด้านการรักษาพยาบาลของผู้ประกันตน 2) สื่อสารให้ HR, welfare, พยาบาลวิชาชีพ, เจ้าหน้าที่ประกันสังคม และลูกจ้างทราบว่า ผู้ประกันตนสามารถเข้าถึงการรักษาภาวะฉุกเฉินบางประเภทได้ภายใต้หลักเกณฑ์ใหม่ของประกันสังคม 3) ใช้เป็นข้อมูลสนับสนุนด้าน employee well-being และ labour welfare โดยเฉพาะในองค์กรที่มีลูกจ้างกลุ่มเสี่ยงโรคหัวใจ โรคหลอดเลือดสมอง หรือโรคไม่ติดต่อเรื้อรังจำนวนมาก 4) บูรณาการเข้ากับระบบ มรท.8001 ในด้าน การอบรม/การสื่อสารสิทธิ, การจัดการสวัสดิการ, และ การดูแลแรงงานหลังเจ็บป่วยหรือกลับเข้าทำงาน เพื่อช่วยให้แรงงานเข้าถึงสิทธิได้รวดเร็วขึ้น 5) ในการตรวจติดตามภายใน องค์กรอาจตรวจว่ามีการสื่อสารสิทธิประโยชน์ประกันสังคมที่สำคัญแก่ลูกจ้างอย่างทั่วถึงหรือไม่ โดยเฉพาะกรณีโรครุนแรงที่ต้องรักษาเร่งด่วน | L6: Active | M6: 3

Sheet กฎหมายในปีล่าสุด
A1: กฎหมายในปีล่าสุด
A2: เกณฑ์การคัดเลือก: เลือกเฉพาะรายการในปีล่าสุดที่สุดของข้อมูล = 2026
A3: จำนวนรายการ | B3: =COUNTA($B$6:$B$1048576) -> 6 | C3: คัดจากคอลัมน์ Date of Issue / Effective Date
A5: Subject | B5: No | C5: Category | D5: Document ID / Reference No. | E5: Legal / Regulatory Title | F5: Date of Issue / Effective Date | G5: Legal Reference Link | H5: Key Legal & Regulatory Requirements | I5: Compliance Implementation Status | J5: (Y) Compliant / (N) Non-Compliant | K5: Implementation Guidance & Evidence Examples | L5: Legal Validity Status | M5: Approval status
A6: ประกาศคณะกรรมการการแพทย์ตามพระราชบัญญัติประกันสังคม | B6: 57 | C6: กฎหมายประกันสังคม | D6: 102381 | E6: ประกาศคณะกรรมการการแพทย์ตามพระราชบัญญัติประกันสังคม เรื่อง หลักเกณฑ์และอัตราค่าบริการทางการแพทย์เพื่อเพิ่มประสิทธิภาพการเข้าถึงการรักษาของผู้ประกันตนในระบบประกันสังคม | F6: 46357 | G6: https://ratchakitcha.soc.go.th/documents/102381.pdf | H6: ประกาศฉบับนี้เป็นกฎหมายที่กำหนด หลักเกณฑ์และอัตราค่าบริการทางการแพทย์เพิ่มเติมเป็นการเฉพาะ เพื่อสนับสนุนการรักษาผู้ประกันตนใน 2 กลุ่มโรคสำคัญ คือ 1) โรคหลอดเลือดสมองอุดตัน โดยเฉพาะหัตถการ Thrombectomy 2) โรคหัวใจและหลอดเลือด โดยเฉพาะการสวนหัวใจ การขยายหลอดเลือดหัวใจ และหัตถการหัวใจเฉพาะทางอื่น ๆ | I6: Implemented | J6: จริง | K6: 1) ทบทวน ทะเบียนกฎหมายและข้อกำหนดที่เกี่ยวข้อง ให้ครอบคลุมประกาศนี้ โดยเฉพาะในส่วนสิทธิประโยชน์ด้านการรักษาพยาบาลของผู้ประกันตน 2) สื่อสารให้ HR, welfare, พยาบาลวิชาชีพ, เจ้าหน้าที่ประกันสังคม และลูกจ้างทราบว่า ผู้ประกันตนสามารถเข้าถึงการรักษาภาวะฉุกเฉินบางประเภทได้ภายใต้หลักเกณฑ์ใหม่ของประกันสังคม 3) ใช้เป็นข้อมูลสนับสนุนด้าน employee well-being และ labour welfare โดยเฉพาะในองค์กรที่มีลูกจ้างกลุ่มเสี่ยงโรคหัวใจ โรคหลอดเลือดสมอง หรือโรคไม่ติดต่อเรื้อรังจำนวนมาก 4) บูรณาการเข้ากับระบบ มรท.8001 ในด้าน การอบรม/การสื่อสารสิทธิ, การจัดการสวัสดิการ, และ การดูแลแรงงานหลังเจ็บป่วยหรือกลับเข้าทำงาน เพื่อช่วยให้แรงงานเข้าถึงสิทธิได้รวดเร็วขึ้น 5) ในการตรวจติดตามภายใน องค์กรอาจตรวจว่ามีการสื่อสารสิทธิประโยชน์ประกันสังคมที่สำคัญแก่ลูกจ้างอย่างทั่วถึงหรือไม่ โดยเฉพาะกรณีโรครุนแรงที่ต้องรักษาเร่งด่วน | L6: Active | M6: 3
A7: ประกาศกระทรวงแรงงาน | B7: 53 | C7: กฎหมายจัดหางาน | D7: 99072 | E7: ประกาศกระทรวงแรงงาน เรื่อง การอนุญาตให้คนต่างด้าวทำงานในราชอาณาจักรเป็นการเฉพาะ สำหรับคนต่างด้าวสัญชาติลาวและเวียดนาม ซึ่งได้รับอนุญาตให้ทำงานถึงวันที่ 13 กุมภาพันธ์ 2569 ตามมติคณะรัฐมนตรีเมื่อวันที่ 2 ธันวาคม 2568 | F7: 46266 | G7: https://ratchakitcha.soc.go.th/documents/99072.pdf | H7: ะกาศฉบับนี้เป็นมาตรการเฉพาะสำหรับ คนต่างด้าวสัญชาติลาวและเวียดนาม ที่ได้รับอนุญาตให้ทำงานอยู่แล้วและสิทธิเดิมสิ้นสุดวันที่ 13 กุมภาพันธ์ 2569 โดยเปิดทางให้ดำเนินการต่ออายุการทำงานในราชอาณาจักรต่อไปภายใต้เงื่อนไขที่กำหนด และให้นายทะเบียนพิจารณาอนุญาตทำงานได้ถึงวันที่ 13 กุมภาพันธ์ 2570 หากเอกสารถูกต้องครบถ้วน | I7: Implemented | J7: จริง | K7: 1) ทบทวน ทะเบียนกฎหมายและข้อกำหนด ให้ครอบคลุมประกาศฉบับนี้ รวมถึงกฎหมายคนเข้าเมือง การบริหารจัดการการทำงานของคนต่างด้าว และข้อกำหนดเรื่องประกันสุขภาพ/ประกันสังคมที่เกี่ยวข้อง 2) จัดทำ บัญชีรายชื่อแรงงานต่างด้าวที่เข้าเงื่อนไข และติดตามวันครบกำหนดของการตรวจสุขภาพ ประกันสุขภาพ การยื่นคำขอ และเอกสารที่ใช้แทนใบอนุญาตทำงานอย่างใกล้ชิด 3) ควบคุม เอกสารสำคัญ เช่น ใบรับคำขอ ใบเสร็จรับเงิน ใบอนุญาตทำงาน หลักฐานการตรวจสุขภาพ หลักฐานประกันสุขภาพ/ประกันสังคม และเอกสารเปลี่ยนนายจ้าง ให้พร้อมต่อการตรวจติดตาม 4) ทบทวนขั้นตอน onboarding, renewal, transfer, labour document control และมอบหมายผู้รับผิดชอบระหว่าง HR, นายจ้าง, ตัวแทน, และผู้รับเหมา ให้ชัดเจน 5) บรรจุประเด็นนี้ไว้ใน internal audit / legal compliance review ของ มรท.8001 โดยตรวจว่ามีแรงงานทำงานก่อนโดยมีเอกสารรองรับถูกต้องหรือไม่ มีการทำประกันครบหรือไม่ และมีแรงงานใดเสี่ยงหลุดสถานะหรือไม่ 6) ใช้ในการอบรมผู้เกี่ยวข้องเพื่อป้องกันความเสี่ยงเรื่อง แรงงานต่างด้าวทำงานโดยเอกสารไม่ครบ, ประกันไม่ถูกต้อง, หรือ เปลี่ยนนายจ้างไม่เป็นไปตามเงื่อนไข ซึ่งอาจกระทบทั้งด้านกฎหมายและการรับรองระบบแรงงาน | L7: Active | M7: 3
A8: ประกาศกระทรวงแรงงาน | B8: 54 | C8: กฎหมายจัดหางาน | D8: 99070 | E8: ประกาศกระทรวงแรงงาน เรื่อง การอนุญาตให้คนต่างด้าวทำงานในราชอาณาจักรเป็นการเฉพาะ สำหรับคนต่างด้าวสัญชาติลาว เมียนมา และเวียดนาม ซึ่งได้รับอนุญาตให้ทำงานถึงวันที่ 31 มีนาคม 2569 ตามมติคณะรัฐมนตรีเมื่อวันที่ 2 ธันวาคม 2568 | F8: 46266 | G8: https://ratchakitcha.soc.go.th/documents/99070.pdf | H8: ประกาศฉบับนี้เป็นมาตรการเฉพาะสำหรับคนต่างด้าว สัญชาติลาว เมียนมา และเวียดนาม ที่ได้รับอนุญาตให้ทำงานอยู่แล้วและสิทธิเดิมสิ้นสุดวันที่ 31 มีนาคม 2569 โดยเปิดทางให้ดำเนินการต่ออายุการทำงานต่อไปภายใต้เงื่อนไขที่กำหนด และเมื่อนายทะเบียนตรวจสอบครบถ้วนแล้ว สามารถอนุญาตทำงานได้ถึงวันที่ 31 มีนาคม 2570 | I8: Implemented | J8: จริง | K8: 1) ทบทวน ทะเบียนกฎหมายและข้อกำหนดที่เกี่ยวข้อง ให้ครอบคลุมประกาศฉบับนี้ รวมถึงกฎหมายคนเข้าเมือง กฎหมายบริหารจัดการการทำงานของคนต่างด้าว และข้อกำหนดเรื่องประกันสุขภาพ/ประกันสังคมที่เกี่ยวข้อง 2) จัดทำ บัญชีรายชื่อแรงงานต่างด้าวที่เข้าเงื่อนไข และติดตามวันครบกำหนดของการตรวจสุขภาพ ประกันสุขภาพ การยื่นคำขอ และเอกสารแทนใบอนุญาตทำงาน 3) ควบคุม เอกสารสำคัญ เช่น ใบรับคำขอ ใบเสร็จรับเงิน ใบอนุญาตทำงาน หลักฐานการตรวจสุขภาพ หลักฐานประกันสุขภาพ/ประกันสังคม และเอกสารเปลี่ยนนายจ้าง ให้พร้อมต่อการตรวจติดตาม 4) ทบทวนขั้นตอน onboarding, renewal, transfer, labour document control ให้ชัดเจนระหว่าง HR, หน่วยงานสนับสนุน, นายจ้าง และผู้รับเหมา 5)บรรจุประเด็นนี้ไว้ใน internal audit / legal compliance review ของ มรท.8001 โดยเฉพาะการตรวจแรงงานต่างด้าวว่าทำงานโดยมีเอกสารรองรับถูกต้องหรือไม่ มีประกันครบหรือไม่ และมีรายใดเสี่ยงหลุดสถานะหรือไม่ | L8: Active | M8: 3
A9: ประกาศคณะกรรมการการแพทย์ตามพระราชบัญญัติประกันสังคม | B9: 56 | C9: กฎหมายประกันสังคม | D9: 102373 | E9: ประกาศคณะกรรมการการแพทย์ตามพระราชบัญญัติประกันสังคม เรื่อง หลักเกณฑ์และอัตราสำหรับประโยชน์ทดแทนในกรณีประสบอันตรายหรือเจ็บป่วยอันมิใช่เนื่องจากการทำงาน | F9: 46083 | G9: https://ratchakitcha.soc.go.th/documents/102373.pdf | H9: ประกาศฉบับนี้เป็น กฎหมายแก้ไขเพิ่มเติม จากประกาศคณะกรรมการการแพทย์ตามพระราชบัญญัติประกันสังคม เรื่องเดียวกัน ลงวันที่ 25 ธันวาคม 2564 และที่แก้ไขเพิ่มเติมภายหลัง โดยในฉบับนี้มีสาระสำคัญ 2 ส่วนหลัก คือ แก้ไขข้อความข้อ 5/1 เดิม และ เพิ่มข้อ 9 ว่าด้วยการผ่าตัดรักษาโรคอ้วนรุนแรง/โรคร่วมจากภาวะอ้วน | I9: Implemented | J9: จริง | K9: 1) ทบทวน ทะเบียนกฎหมายและข้อกำหนดที่เกี่ยวข้อง ให้ครอบคลุมประกาศฉบับนี้ โดยเฉพาะในส่วนสิทธิประโยชน์ด้านการแพทย์ของผู้ประกันตน 2) ประสาน HR, หน่วยงานสวัสดิการ, แพทย์/พยาบาลประจำสถานประกอบกิจการ หรือผู้ดูแล employee well-being เพื่อ สื่อสารสิทธิการรักษา แก่ลูกจ้างที่อาจเข้าเกณฑ์ 3) ใช้เป็นข้อมูลสนับสนุน โครงการส่งเสริมสุขภาพแรงงาน เช่น การควบคุมน้ำหนัก การป้องกันโรคไม่ติดต่อเรื้อรัง และการดูแลแรงงานที่มีความเสี่ยงด้านสุขภาพ 4) ในการตรวจติดตามภายใน มรท.8001 องค์กรอาจตรวจว่าได้มีการ สื่อสารสิทธิประกันสังคมและสิทธิด้านสุขภาพ ให้ลูกจ้างอย่างเหมาะสมหรือไม่ 5) หากองค์กรมีแรงงานที่มีภาวะอ้วนรุนแรงหรือโรคร่วมจำนวนมาก ประกาศนี้อาจช่วยลดผลกระทบด้านสุขภาพ การขาดงาน และเพิ่มโอกาสกลับสู่การทำงานอย่างมีประสิทธิภาพได้ | L9: Active | M9: 3
A10: ประกาศคณะกรรมการส่งเสริมการพัฒนาฝีมือแรงงาน | B10: 52 | C10: กฎหมายพัฒนาฝีมือแรงงาน | D10: 101869 | E10: ประกาศคณะกรรมการส่งเสริมการพัฒนาฝีมือแรงงาน เรื่อง หลักเกณฑ์การใช้จ่ายเงินเพื่อช่วยเหลือหรืออุดหนุนจากกองทุนพัฒนาฝีมือแรงงาน (ฉบับที่ ๒) | F10: 1/21/2026 | G10: https://ratchakitcha.soc.go.th/documents/101869.pdf | H10: เหตุผลหลักของการออกประกาศฉบับนี้ คือเพื่อแก้ไขเพิ่มเติมหลักเกณฑ์เดิมให้ครอบคลุมกรณีที่ผู้ประกอบกิจการจัดให้มีการฝึกอบรมฝีมือแรงงานแก่ลูกจ้างของตนในหลักสูตรเฉพาะที่เกี่ยวข้องกับ นวัตกรรมหรือปัญญาประดิษฐ์ /AI เพื่อรองรับการพัฒนาเทคโนโลยี และเพื่อให้หลักเกณฑ์การใช้จ่ายเงินจากกองทุนพัฒนาฝีมือแรงงานมีความเหมาะสมยิ่งขึ้น | I10: Implemented | J10: จริง | K10: 1) บันทึกกฎหมายฉบับนี้ไว้ใน ทะเบียนกฎหมายและข้อกำหนดที่เกี่ยวข้อง หากองค์กรมีการใช้สิทธิจากกองทุนพัฒนาฝีมือแรงงาน 2) จัดทำหรือทบทวน ขั้นตอนการวางแผนอบรม การขออนุมัติหลักสูตร การเก็บหลักฐานการฝึกอบรม และการยื่นคำขอรับเงินอุดหนุน ให้สอดคล้องกับประกาศฉบับนี้ 3) ใช้เป็นฐานสนับสนุนการพัฒนาทักษะแรงงานในหลักสูตรที่เกี่ยวข้องกับ นวัตกรรม/AI ซึ่งช่วยยกระดับความสามารถของแรงงานและความพร้อมขององค์กรในระยะยาว 4) ในการตรวจติดตามภายใน ควรตรวจดูว่าองค์กรมี หลักฐานการอบรม, การเห็นชอบหลักสูตร, การคำนวณสิทธิ, และการยื่นคำขอภายในกำหนดเวลา ครบถ้วนหรือไม่ 5) ในเชิงระบบ เอกสารนี้มีผลต่อ การควบคุมเอกสาร, การติดตามความสอดคล้องตามกฎหมาย, การอบรม และการจัดการบันทึกหลักฐาน มากกว่าการกำหนดสิทธิขั้นพื้นฐานของลูกจ้างโดยตรง | L10: Active | M10: 3
A11: ประกาศคณะกรรมการการแพทย์ตามพระราชบัญญัติประกันสังคม | B11: 55 | C11: กฎหมายประกันสังคม | D11: 101606 | E11: ประกาศคณะกรรมการการแพทย์ตามพระราชบัญญัติประกันสังคม เรื่อง หลักเกณฑ์และอัตราค่าส่งเสริมสุขภาพและป้องกันโรคสำหรับประโยชน์ทดแทนในกรณีประสบอันตรายหรือเจ็บป่วยอันมิใช่เนื่องจากการทำงาน พ.ศ. ๒๕๖๘ | F11: 1/15/2026 | G11: https://ratchakitcha.soc.go.th/documents/101606.pdf | H11: ประกาศฉบับนี้เป็น กฎหมายแก้ไขเพิ่มเติม โดยแก้ไขข้อความใน ข้อ ๒/๒ ของประกาศคณะกรรมการการแพทย์ตามพระราชบัญญัติประกันสังคม เรื่อง หลักเกณฑ์และอัตราค่าส่งเสริมสุขภาพและป้องกันโรคสำหรับประโยชน์ทดแทนในกรณีประสบอันตรายหรือเจ็บป่วยอันมิใช่เนื่องจากการทำงาน ลงวันที่ ๑๖ ธันวาคม ๒๕๕๙ ซึ่งต่อมาได้มีการแก้ไขเพิ่มเติมอีกครั้งโดยประกาศ พ.ศ. ๒๕๖๓ ลงวันที่ ๙ ธันวาคม ๒๕๖๓ แล้วให้ใช้ข้อความใหม่แทน | I11: Implemented | J11: จริง | K11: 1) ทบทวน ทะเบียนกฎหมายและข้อกำหนดที่เกี่ยวข้อง ให้ครอบคลุมประกาศฉบับนี้ หากองค์กรมีลูกจ้างที่เป็นผู้ประกันตนอายุ ๕๐ ปีขึ้นไป 2) ใช้เป็นข้อมูลในการจัดทำหรือสื่อสาร แผนสวัสดิการและส่งเสริมสุขภาพแรงงาน ร่วมกับ HR, Admin, Safety หรือพยาบาลวิชาชีพประจำสถานประกอบกิจการ 3) ประชาสัมพันธ์สิทธิให้ลูกจ้างกลุ่มเป้าหมายทราบอย่างทั่วถึง เช่น ช่วงเวลาใช้สิทธิ สถานพยาบาลที่กำหนด และเงื่อนไขการรับบริการ 4) ใช้เป็นหลักฐานสนับสนุนด้าน labour welfare / employee well-being ในระบบ มรท.8001 และในการตรวจติดตามภายใน องค์กรอาจตรวจว่ามีการสื่อสารสิทธิประโยชน์ด้านสุขภาพแก่ลูกจ้างอย่างเหมาะสมหรือไม่ 5) หากองค์กรมีโครงการสร้างเสริมสุขภาพพนักงานอยู่แล้ว สามารถบูรณาการข้อมูลนี้เข้ากับกิจกรรมด้านสุขภาพประจำปี เพื่อยกระดับคุณภาพชีวิตแรงงานและลดความเสี่ยงด้านสุขภาพจากโรคตามฤดูกาล | L11: Active | M11: 3

Sheet Data_Helper
A1: Source_Row | B1: No | C1: Legal_Title | D1: Category | E1: Issue_Date | F1: Year | G1: Year_Month | H1: Status_Raw | I1: Status_Norm | J1: Validity_Raw | K1: Validity_Norm | L1: Compliant | M1: Evidence | N1: Is_Implemented | O1: Is_Identified | P1: Is_Evaluated | Q1: Is_Active | R1: Is_Inactive | S1: Is_Blank_Validity | T1: Is_Active_Pending | U1: Has_Blank_Date | V1: Has_Blank_Evidence | W1: Data_Issue_Flag | X1: Reference_Link | Y1: Document_ID | Z1: Subject_Type
A2: 2 | B2: =Raw_Data_Copy!B2 -> 1 | C2: =Raw_Data_Copy!E2 -> พระราชบัญญัติคุ้มครองแรงงาน พ.ศ. 2541 และที่แก้ไขเพิ่มเติม | D2: =Raw_Data_Copy!C2 -> กฎหมายคุ้มครองแรงงาน | E2: =Raw_Data_Copy!F2 -> 2/20/1998 | F2: =IF(E2="","",YEAR(E2)) -> #VALUE! | G2: =IF(E2="","",TEXT(E2,"yyyy-mm")) -> 2/20/1998 | H2: =Raw_Data_Copy!I2 -> Implemented | I2: =IF(H2="","",IF(OR(LOWER(TRIM(H2))="implemented",LOWER(TRIM(H2))="implement"),"Implemented",IF(LOWER(TRIM(H2))="identified","Identified",IF(LOWER(TRIM(H2))="evaluated","Evaluated",IF(LOWER(TRIM(H2))="under review","Under Review",H2))))) -> Implemented | J2: =Raw_Data_Copy!L2 -> Active | K2: =IF(J2="","",IF(LOWER(TRIM(J2))="active","Active",IF(LOWER(TRIM(J2))="inactive","Inactive",J2))) -> Active | L2: =Raw_Data_Copy!J2 -> จริง | M2: =Raw_Data_Copy!K2 -> สื่อสารผ่าน e-smart/ idoc / ข้อบังคับการทำงาน | N2: =--(I2="Implemented") -> 1 | O2: =--(I2="Identified") -> 0 | P2: =--(I2="Evaluated") -> 0 | Q2: =--(K2="Active") -> 1 | R2: =--(K2="Inactive") -> 0 | S2: =--(K2="") -> 0 | T2: =--(AND(K2="Active",I2<>"Implemented")) -> 0 | U2: =--(E2="") -> 0 | V2: =--(M2="") -> 0 | W2: =--(OR(U2=1,S2=1,V2=1)) -> 0 | X2: =Raw_Data_Copy!G2 -> https://legal.labour.go.th/images/law/Protection2541/2541_labour_protection.pdf | Y2: =Raw_Data_Copy!D2 -> 0 | Z2: =Raw_Data_Copy!A2 -> พระราชบัญญัติ
A3: 3 | B3: =Raw_Data_Copy!B3 -> 2 | C3: =Raw_Data_Copy!E3 -> พระราชบัญญัติส่งเสริมการพัฒนาฝีมือแรงงาน พ.ศ. 2545 และที่แก้ไขเพิ่มเติม | D3: =Raw_Data_Copy!C3 -> กฎหมายพัฒนาฝีมือแรงงาน | E3: =Raw_Data_Copy!F3 -> 9/22/2002 | F3: =IF(E3="","",YEAR(E3)) -> #VALUE! | G3: =IF(E3="","",TEXT(E3,"yyyy-mm")) -> 9/22/2002 | H3: =Raw_Data_Copy!I3 -> Implemented | I3: =IF(H3="","",IF(OR(LOWER(TRIM(H3))="implemented",LOWER(TRIM(H3))="implement"),"Implemented",IF(LOWER(TRIM(H3))="identified","Identified",IF(LOWER(TRIM(H3))="evaluated","Evaluated",IF(LOWER(TRIM(H3))="under review","Under Review",H3))))) -> Implemented | J3: =Raw_Data_Copy!L3 -> Active | K3: =IF(J3="","",IF(LOWER(TRIM(J3))="active","Active",IF(LOWER(TRIM(J3))="inactive","Inactive",J3))) -> Active | L3: =Raw_Data_Copy!J3 -> จริง | M3: =Raw_Data_Copy!K3 -> สื่อสารผ่าน e-smart/ idoc / ขั้นตอนการปฏิบัติงานเกี่ยวกับพัฒนาฝีมือแรงงาน | N3: =--(I3="Implemented") -> 1 | O3: =--(I3="Identified") -> 0 | P3: =--(I3="Evaluated") -> 0 | Q3: =--(K3="Active") -> 1 | R3: =--(K3="Inactive") -> 0 | S3: =--(K3="") -> 0 | T3: =--(AND(K3="Active",I3<>"Implemented")) -> 0 | U3: =--(E3="") -> 0 | V3: =--(M3="") -> 0 | W3: =--(OR(U3=1,S3=1,V3=1)) -> 0 | X3: =Raw_Data_Copy!G3 -> https://idev.dsd.go.th/~law/qr1/01%20%A1%AE%CB%C1%D2%C2%B7%D5%E8%E0%A1%D5%E8%C2%C7%A2%E9%CD%A7%A1%D1%BA%A1%D2%C3%BE%D1%B2%B9%D2%BD%D5%C1%D7%CD%E1%C3%A7%A7%D2%B9/%20%BE%C3%D0%C3%D2%AA%BA%D1%AD%AD%D1%B5%D4/1.%20%BE%C3%D0%C3%D2%AA%BA%D1%AD%AD%D1%B5%D4%CA%E8%A7%E0%CA%C3%D4%C1%A1%D2%C3%BE%D1%B2%B9%D2%BD%D5%C1%D7%CD%E1%C3%A7%A7%D2%B9%20%BE.%C8.2545%20%E1%C5%D0%B7%D5%E8%E1%A1%E9%E4%A2%E0%BE%D4%E8%C1%E0%B5%D4%C1.pdf | Y3: =Raw_Data_Copy!D3 -> 0 | Z3: =Raw_Data_Copy!A3 -> พระราชบัญญัติ
A4: 4 | B4: =Raw_Data_Copy!B4 -> 3 | C4: =Raw_Data_Copy!E4 -> พระราชบัญญัติแรงงานสัมพันธ์ พ.ศ. 2518 | D4: =Raw_Data_Copy!C4 -> กฎหมายแรงงานสัมพันธ์ | E4: =Raw_Data_Copy!F4 -> 2/14/1975 | F4: =IF(E4="","",YEAR(E4)) -> #VALUE! | G4: =IF(E4="","",TEXT(E4,"yyyy-mm")) -> 2/14/1975 | H4: =Raw_Data_Copy!I4 -> Implemented | I4: =IF(H4="","",IF(OR(LOWER(TRIM(H4))="implemented",LOWER(TRIM(H4))="implement"),"Implemented",IF(LOWER(TRIM(H4))="identified","Identified",IF(LOWER(TRIM(H4))="evaluated","Evaluated",IF(LOWER(TRIM(H4))="under review","Under Review",H4))))) -> Implemented | J4: =Raw_Data_Copy!L4 -> Active | K4: =IF(J4="","",IF(LOWER(TRIM(J4))="active","Active",IF(LOWER(TRIM(J4))="inactive","Inactive",J4))) -> Active | L4: =Raw_Data_Copy!J4 -> จริง | M4: =Raw_Data_Copy!K4 -> สื่อสารผ่าน e-smart/ idoc | N4: =--(I4="Implemented") -> 1 | O4: =--(I4="Identified") -> 0 | P4: =--(I4="Evaluated") -> 0 | Q4: =--(K4="Active") -> 1 | R4: =--(K4="Inactive") -> 0 | S4: =--(K4="") -> 0 | T4: =--(AND(K4="Active",I4<>"Implemented")) -> 0 | U4: =--(E4="") -> 0 | V4: =--(M4="") -> 0 | W4: =--(OR(U4=1,S4=1,V4=1)) -> 0 | X4: =Raw_Data_Copy!G4 -> https://legal.labour.go.th/images/law/Relation2518/labour_relation2518.pdf | Y4: =Raw_Data_Copy!D4 -> 0 | Z4: =Raw_Data_Copy!A4 -> พระราชบัญญัติ
A5: 5 | B5: =Raw_Data_Copy!B5 -> 4 | C5: =Raw_Data_Copy!E5 -> พระราชบัญญัติป้องกันและปราบปรามการค้ามนุษย์ พ.ศ. 2551 และฉบับที่แก้ไขเพิ่มเติม | D5: =Raw_Data_Copy!C5 -> กฎหมาย อื่น ๆ | E5: =Raw_Data_Copy!F5 -> 12/30/2008 | F5: =IF(E5="","",YEAR(E5)) -> #VALUE! | G5: =IF(E5="","",TEXT(E5,"yyyy-mm")) -> 12/30/2008 | H5: =Raw_Data_Copy!I5 -> Implemented | I5: =IF(H5="","",IF(OR(LOWER(TRIM(H5))="implemented",LOWER(TRIM(H5))="implement"),"Implemented",IF(LOWER(TRIM(H5))="identified","Identified",IF(LOWER(TRIM(H5))="evaluated","Evaluated",IF(LOWER(TRIM(H5))="under review","Under Review",H5))))) -> Implemented | J5: =Raw_Data_Copy!L5 -> Active | K5: =IF(J5="","",IF(LOWER(TRIM(J5))="active","Active",IF(LOWER(TRIM(J5))="inactive","Inactive",J5))) -> Active | L5: =Raw_Data_Copy!J5 -> จริง | M5: =Raw_Data_Copy!K5 -> สื่อสารผ่าน e-smart/ idoc | N5: =--(I5="Implemented") -> 1 | O5: =--(I5="Identified") -> 0 | P5: =--(I5="Evaluated") -> 0 | Q5: =--(K5="Active") -> 1 | R5: =--(K5="Inactive") -> 0 | S5: =--(K5="") -> 0 | T5: =--(AND(K5="Active",I5<>"Implemented")) -> 0 | U5: =--(E5="") -> 0 | V5: =--(M5="") -> 0 | W5: =--(OR(U5=1,S5=1,V5=1)) -> 0 | X5: =Raw_Data_Copy!G5 -> https://web.parliament.go.th/aseanrelated_law/files/file_20170817115531_0.pdf | Y5: =Raw_Data_Copy!D5 -> 0 | Z5: =Raw_Data_Copy!A5 -> พระราชบัญญัติ
A6: 6 | B6: =Raw_Data_Copy!B6 -> 5 | C6: =Raw_Data_Copy!E6 -> พระราชบัญญัติประกันสังคม พ.ศ. 2533 และฉบับที่แก้ไขเพิ่มเติม | D6: =Raw_Data_Copy!C6 -> กฎหมายประกันสังคม | E6: =Raw_Data_Copy!F6 -> 12/30/2008 | F6: =IF(E6="","",YEAR(E6)) -> #VALUE! | G6: =IF(E6="","",TEXT(E6,"yyyy-mm")) -> 12/30/2008 | H6: =Raw_Data_Copy!I6 -> Implemented | I6: =IF(H6="","",IF(OR(LOWER(TRIM(H6))="implemented",LOWER(TRIM(H6))="implement"),"Implemented",IF(LOWER(TRIM(H6))="identified","Identified",IF(LOWER(TRIM(H6))="evaluated","Evaluated",IF(LOWER(TRIM(H6))="under review","Under Review",H6))))) -> Implemented | J6: =Raw_Data_Copy!L6 -> Active | K6: =IF(J6="","",IF(LOWER(TRIM(J6))="active","Active",IF(LOWER(TRIM(J6))="inactive","Inactive",J6))) -> Active | L6: =Raw_Data_Copy!J6 -> จริง | M6: =Raw_Data_Copy!K6 -> สื่อสารผ่าน e-smart/ idoc | N6: =--(I6="Implemented") -> 1 | O6: =--(I6="Identified") -> 0 | P6: =--(I6="Evaluated") -> 0 | Q6: =--(K6="Active") -> 1 | R6: =--(K6="Inactive") -> 0 | S6: =--(K6="") -> 0 | T6: =--(AND(K6="Active",I6<>"Implemented")) -> 0 | U6: =--(E6="") -> 0 | V6: =--(M6="") -> 0 | W6: =--(OR(U6=1,S6=1,V6=1)) -> 0 | X6: =Raw_Data_Copy!G6 -> https://www.mol.go.th/wp-content/uploads/sites/2/2021/02/2-%E0%B8%9E%E0%B8%A3%E0%B8%9A.%E0%B8%9B%E0%B8%A3%E0%B8%B0%E0%B8%81%E0%B8%B1%E0%B8%99%E0%B8%AA%E0%B8%B1%E0%B8%87%E0%B8%84%E0%B8%A1-%E0%B8%9E.%E0%B8%A8.-2533.pdf | Y6: =Raw_Data_Copy!D6 -> 0 | Z6: =Raw_Data_Copy!A6 -> พระราชบัญญัติ
A7: 7 | B7: =Raw_Data_Copy!B7 -> 6 | C7: =Raw_Data_Copy!E7 -> พระราชบัญญัติเงินทดแทน พ.ศ. 2537 และฉบับที่แก้ไขเพิ่มเติม | D7: =Raw_Data_Copy!C7 -> กฎหมายประกันสังคม | E7: =Raw_Data_Copy!F7 -> 6/14/1994 | F7: =IF(E7="","",YEAR(E7)) -> #VALUE! | G7: =IF(E7="","",TEXT(E7,"yyyy-mm")) -> 6/14/1994 | H7: =Raw_Data_Copy!I7 -> Implemented | I7: =IF(H7="","",IF(OR(LOWER(TRIM(H7))="implemented",LOWER(TRIM(H7))="implement"),"Implemented",IF(LOWER(TRIM(H7))="identified","Identified",IF(LOWER(TRIM(H7))="evaluated","Evaluated",IF(LOWER(TRIM(H7))="under review","Under Review",H7))))) -> Implemented | J7: =Raw_Data_Copy!L7 -> Active | K7: =IF(J7="","",IF(LOWER(TRIM(J7))="active","Active",IF(LOWER(TRIM(J7))="inactive","Inactive",J7))) -> Active | L7: =Raw_Data_Copy!J7 -> จริง | M7: =Raw_Data_Copy!K7 -> สื่อสารผ่าน e-smart/ idoc | N7: =--(I7="Implemented") -> 1 | O7: =--(I7="Identified") -> 0 | P7: =--(I7="Evaluated") -> 0 | Q7: =--(K7="Active") -> 1 | R7: =--(K7="Inactive") -> 0 | S7: =--(K7="") -> 0 | T7: =--(AND(K7="Active",I7<>"Implemented")) -> 0 | U7: =--(E7="") -> 0 | V7: =--(M7="") -> 0 | W7: =--(OR(U7=1,S7=1,V7=1)) -> 0 | X7: =Raw_Data_Copy!G7 -> https://www.sso.go.th/wpr/assets/upload/files_storage/sso_th/84244ea51a2464c0713a98ddd8cc0955.pdf | Y7: =Raw_Data_Copy!D7 -> 0 | Z7: =Raw_Data_Copy!A7 -> พระราชบัญญัติ
A8: 8 | B8: =Raw_Data_Copy!B8 -> 7 | C8: =Raw_Data_Copy!E8 -> พระราชกฤษฎีกา กำหนดระยะเวลาเริ่มดำเนินการจัดเก็บเงินสะสมและเงินสมทบกองทุนสงเคราะห์ลูกจ้าง พ.ศ. 2567 | D8: =Raw_Data_Copy!C8 -> กฎหมายคุ้มครองแรงงาน | E8: =Raw_Data_Copy!F8 -> 11/15/2024 | F8: =IF(E8="","",YEAR(E8)) -> #VALUE! | G8: =IF(E8="","",TEXT(E8,"yyyy-mm")) -> 11/15/2024 | H8: =Raw_Data_Copy!I8 -> Evaluated | I8: =IF(H8="","",IF(OR(LOWER(TRIM(H8))="implemented",LOWER(TRIM(H8))="implement"),"Implemented",IF(LOWER(TRIM(H8))="identified","Identified",IF(LOWER(TRIM(H8))="evaluated","Evaluated",IF(LOWER(TRIM(H8))="under review","Under Review",H8))))) -> Evaluated | J8: =Raw_Data_Copy!L8 -> Active | K8: =IF(J8="","",IF(LOWER(TRIM(J8))="active","Active",IF(LOWER(TRIM(J8))="inactive","Inactive",J8))) -> Active | L8: =Raw_Data_Copy!J8 -> จริง | M8: =Raw_Data_Copy!K8 -> สื่อสารผ่าน e-smart/ idoc | N8: =--(I8="Implemented") -> 0 | O8: =--(I8="Identified") -> 0 | P8: =--(I8="Evaluated") -> 1 | Q8: =--(K8="Active") -> 1 | R8: =--(K8="Inactive") -> 0 | S8: =--(K8="") -> 0 | T8: =--(AND(K8="Active",I8<>"Implemented")) -> 1 | U8: =--(E8="") -> 0 | V8: =--(M8="") -> 0 | W8: =--(OR(U8=1,S8=1,V8=1)) -> 0 | X8: =Raw_Data_Copy!G8 -> https://legal.labour.go.th/images/law/Protection2541/2567/EWF_14-11-67.pdf | Y8: =Raw_Data_Copy!D8 -> 0 | Z8: =Raw_Data_Copy!A8 -> พระราชกฤษฎีกา
A9: 9 | B9: =Raw_Data_Copy!B9 -> 8 | C9: =Raw_Data_Copy!E9 -> กฎกระทรวง กำหนดค่าล่วงเวลาและค่าตอบแทนการทำงานที่เกินวันละแปดชั่วโมง ในงานเฝ้าดูแลสถานที่หรือทรัพย์สินอันเป็นหน้าที่การทำงานปกติของลูกจ้าง พ.ศ. 2568 | D9: =Raw_Data_Copy!C9 -> กฎหมายคุ้มครองแรงงาน | E9: =Raw_Data_Copy!F9 -> 4/24/2025 | F9: =IF(E9="","",YEAR(E9)) -> #VALUE! | G9: =IF(E9="","",TEXT(E9,"yyyy-mm")) -> 4/24/2025 | H9: =Raw_Data_Copy!I9 -> Evaluated | I9: =IF(H9="","",IF(OR(LOWER(TRIM(H9))="implemented",LOWER(TRIM(H9))="implement"),"Implemented",IF(LOWER(TRIM(H9))="identified","Identified",IF(LOWER(TRIM(H9))="evaluated","Evaluated",IF(LOWER(TRIM(H9))="under review","Under Review",H9))))) -> Evaluated | J9: =Raw_Data_Copy!L9 -> Active | K9: =IF(J9="","",IF(LOWER(TRIM(J9))="active","Active",IF(LOWER(TRIM(J9))="inactive","Inactive",J9))) -> Active | L9: =Raw_Data_Copy!J9 -> จริง | M9: =Raw_Data_Copy!K9 -> สื่อสารผ่าน e-smart/ idoc | N9: =--(I9="Implemented") -> 0 | O9: =--(I9="Identified") -> 0 | P9: =--(I9="Evaluated") -> 1 | Q9: =--(K9="Active") -> 1 | R9: =--(K9="Inactive") -> 0 | S9: =--(K9="") -> 0 | T9: =--(AND(K9="Active",I9<>"Implemented")) -> 1 | U9: =--(E9="") -> 0 | V9: =--(M9="") -> 0 | W9: =--(OR(U9=1,S9=1,V9=1)) -> 0 | X9: =Raw_Data_Copy!G9 -> https://ratchakitcha.soc.go.th/documents/68372.pdf | Y9: =Raw_Data_Copy!D9 -> 68372 | Z9: =Raw_Data_Copy!A9 -> กฎกระทรวง
A10: 10 | B10: =Raw_Data_Copy!B10 -> 9 | C10: =Raw_Data_Copy!E10 -> กฎกระทรวง กำหนดหลักเกณฑ์และวิธีการจัดการสงเคราะห์แก่ลูกจ้าง ในกรณีที่ลูกจ้างออกจากงานหรือตาย พ.ศ. 2567 | D10: =Raw_Data_Copy!C10 -> กฎหมายคุ้มครองแรงงาน | E10: =Raw_Data_Copy!F10 -> 11/21/2025 | F10: =IF(E10="","",YEAR(E10)) -> #VALUE! | G10: =IF(E10="","",TEXT(E10,"yyyy-mm")) -> 11/21/2025 | H10: =Raw_Data_Copy!I10 -> Implemented | I10: =IF(H10="","",IF(OR(LOWER(TRIM(H10))="implemented",LOWER(TRIM(H10))="implement"),"Implemented",IF(LOWER(TRIM(H10))="identified","Identified",IF(LOWER(TRIM(H10))="evaluated","Evaluated",IF(LOWER(TRIM(H10))="under review","Under Review",H10))))) -> Implemented | J10: =Raw_Data_Copy!L10 -> Inactive | K10: =IF(J10="","",IF(LOWER(TRIM(J10))="active","Active",IF(LOWER(TRIM(J10))="inactive","Inactive",J10))) -> Inactive | L10: =Raw_Data_Copy!J10 -> จริง | M10: =Raw_Data_Copy!K10 -> สื่อสารผ่าน e-smart/ idoc | N10: =--(I10="Implemented") -> 1 | O10: =--(I10="Identified") -> 0 | P10: =--(I10="Evaluated") -> 0 | Q10: =--(K10="Active") -> 0 | R10: =--(K10="Inactive") -> 1 | S10: =--(K10="") -> 0 | T10: =--(AND(K10="Active",I10<>"Implemented")) -> 0 | U10: =--(E10="") -> 0 | V10: =--(M10="") -> 0 | W10: =--(OR(U10=1,S10=1,V10=1)) -> 0 | X10: =Raw_Data_Copy!G10 -> https://legal.labour.go.th/images/law/Protection2541/2567/EWF2_14-11-67.pdf | Y10: =Raw_Data_Copy!D10 -> 0 | Z10: =Raw_Data_Copy!A10 -> กฎกระทรวง
A11: 11 | B11: =Raw_Data_Copy!B11 -> 10 | C11: =Raw_Data_Copy!E11 -> กฎกระทรวง กำหนดอัตราเงินสะสมและเงินสมทบกองทุนสงเคราะห์ลูกจ้าง พ.ศ. 2567 | D11: =Raw_Data_Copy!C11 -> กฎหมายคุ้มครองแรงงาน | E11: =Raw_Data_Copy!F11 -> 11/22/2025 | F11: =IF(E11="","",YEAR(E11)) -> #VALUE! | G11: =IF(E11="","",TEXT(E11,"yyyy-mm")) -> 11/22/2025 | H11: =Raw_Data_Copy!I11 -> Evaluated | I11: =IF(H11="","",IF(OR(LOWER(TRIM(H11))="implemented",LOWER(TRIM(H11))="implement"),"Implemented",IF(LOWER(TRIM(H11))="identified","Identified",IF(LOWER(TRIM(H11))="evaluated","Evaluated",IF(LOWER(TRIM(H11))="under review","Under Review",H11))))) -> Evaluated | J11: =Raw_Data_Copy!L11 -> Inactive | K11: =IF(J11="","",IF(LOWER(TRIM(J11))="active","Active",IF(LOWER(TRIM(J11))="inactive","Inactive",J11))) -> Inactive | L11: =Raw_Data_Copy!J11 -> จริง | M11: =Raw_Data_Copy!K11 -> สื่อสารผ่าน e-smart/ idoc | N11: =--(I11="Implemented") -> 0 | O11: =--(I11="Identified") -> 0 | P11: =--(I11="Evaluated") -> 1 | Q11: =--(K11="Active") -> 0 | R11: =--(K11="Inactive") -> 1 | S11: =--(K11="") -> 0 | T11: =--(AND(K11="Active",I11<>"Implemented")) -> 0 | U11: =--(E11="") -> 0 | V11: =--(M11="") -> 0 | W11: =--(OR(U11=1,S11=1,V11=1)) -> 0 | X11: =Raw_Data_Copy!G11 -> https://legal.labour.go.th/images/law/Protection2541/2567/EWF1_14-11-67.pdf | Y11: =Raw_Data_Copy!D11 -> 0 | Z11: =Raw_Data_Copy!A11 -> กฎกระทรวง
A12: 12 | B12: =Raw_Data_Copy!B12 -> 11 | C12: =Raw_Data_Copy!E12 -> กฎกระทรวง กำหนดประเภทของสถานประกอบกิจการและการดำเนินการของสถานประกอบกิจการในการป้องกันและแก้ไขปัญหาการตั้งครรภ์ในวัยรุ่นแก่ลูกจ้างซึ่งเป็นวัยรุ่น พ.ศ. 2561 | D12: =Raw_Data_Copy!C12 -> กฎหมาย อื่น ๆ | E12: =Raw_Data_Copy!F12 -> 11/16/2018 | F12: =IF(E12="","",YEAR(E12)) -> #VALUE! | G12: =IF(E12="","",TEXT(E12,"yyyy-mm")) -> 11/16/2018 | H12: =Raw_Data_Copy!I12 -> Evaluated | I12: =IF(H12="","",IF(OR(LOWER(TRIM(H12))="implemented",LOWER(TRIM(H12))="implement"),"Implemented",IF(LOWER(TRIM(H12))="identified","Identified",IF(LOWER(TRIM(H12))="evaluated","Evaluated",IF(LOWER(TRIM(H12))="under review","Under Review",H12))))) -> Evaluated | J12: =Raw_Data_Copy!L12 -> Active | K12: =IF(J12="","",IF(LOWER(TRIM(J12))="active","Active",IF(LOWER(TRIM(J12))="inactive","Inactive",J12))) -> Active | L12: =Raw_Data_Copy!J12 -> จริง | M12: =Raw_Data_Copy!K12 -> สื่อสารผ่าน e-smart/ idoc | N12: =--(I12="Implemented") -> 0 | O12: =--(I12="Identified") -> 0 | P12: =--(I12="Evaluated") -> 1 | Q12: =--(K12="Active") -> 1 | R12: =--(K12="Inactive") -> 0 | S12: =--(K12="") -> 0 | T12: =--(AND(K12="Active",I12<>"Implemented")) -> 1 | U12: =--(E12="") -> 0 | V12: =--(M12="") -> 0 | W12: =--(OR(U12=1,S12=1,V12=1)) -> 0 | X12: =Raw_Data_Copy!G12 -> https://legal.labour.go.th/images/law/Protection2541/2561_21.PDF | Y12: =Raw_Data_Copy!D12 -> 0 | Z12: =Raw_Data_Copy!A12 -> กฎกระทรวง
A13: 13 | B13: =Raw_Data_Copy!B13 -> 12 | C13: =Raw_Data_Copy!E13 -> กฎกระทรวง ว่าด้วยการจัดสวัสดิการในสถานประกอบกิจการ พ.ศ. 2548 | D13: =Raw_Data_Copy!C13 -> กฎหมายคุ้มครองแรงงาน | E13: =Raw_Data_Copy!F13 -> 3/29/2005 | F13: =IF(E13="","",YEAR(E13)) -> #VALUE! | G13: =IF(E13="","",TEXT(E13,"yyyy-mm")) -> 3/29/2005 | H13: =Raw_Data_Copy!I13 -> Implemented | I13: =IF(H13="","",IF(OR(LOWER(TRIM(H13))="implemented",LOWER(TRIM(H13))="implement"),"Implemented",IF(LOWER(TRIM(H13))="identified","Identified",IF(LOWER(TRIM(H13))="evaluated","Evaluated",IF(LOWER(TRIM(H13))="under review","Under Review",H13))))) -> Implemented | J13: =Raw_Data_Copy!L13 -> Active | K13: =IF(J13="","",IF(LOWER(TRIM(J13))="active","Active",IF(LOWER(TRIM(J13))="inactive","Inactive",J13))) -> Active | L13: =Raw_Data_Copy!J13 -> จริง | M13: =Raw_Data_Copy!K13 -> สื่อสารผ่าน e-smart/ idoc | N13: =--(I13="Implemented") -> 1 | O13: =--(I13="Identified") -> 0 | P13: =--(I13="Evaluated") -> 0 | Q13: =--(K13="Active") -> 1 | R13: =--(K13="Inactive") -> 0 | S13: =--(K13="") -> 0 | T13: =--(AND(K13="Active",I13<>"Implemented")) -> 0 | U13: =--(E13="") -> 0 | V13: =--(M13="") -> 0 | W13: =--(OR(U13=1,S13=1,V13=1)) -> 0 | X13: =Raw_Data_Copy!G13 -> https://legal.labour.go.th/images/law/Protection2541/2541_17.pdf | Y13: =Raw_Data_Copy!D13 -> 0 | Z13: =Raw_Data_Copy!A13 -> กฎกระทรวง
... A75: 75 | B75: =Raw_Data_Copy!B75 -> 74 | C75: =Raw_Data_Copy!E75 -> กฎกระทรวง การอนุญาตเป็นผู้ชำนาญการด้านความปลอดภัย อาชีวอนามัย และสภาพแวดล้อมในการทำงาน พ.ศ. 2567 | D75: =Raw_Data_Copy!C75 -> กฎหมายความปลอดภัย อาชีวอนามัย และสภาพแวดล้อมในการทำงาน | E75: =Raw_Data_Copy!F75 -> 11/20/2024 | F75: =IF(E75="","",YEAR(E75)) -> #VALUE! | G75: =IF(E75="","",TEXT(E75,"yyyy-mm")) -> 11/20/2024 | H75: =Raw_Data_Copy!I75 -> Implemented | I75: =IF(H75="","",IF(OR(LOWER(TRIM(H75))="implemented",LOWER(TRIM(H75))="implement"),"Implemented",IF(LOWER(TRIM(H75))="identified","Identified",IF(LOWER(TRIM(H75))="evaluated","Evaluated",IF(LOWER(TRIM(H75))="under review","Under Review",H75))))) -> Implemented | J75: =Raw_Data_Copy!L75 -> Active | K75: =IF(J75="","",IF(LOWER(TRIM(J75))="active","Active",IF(LOWER(TRIM(J75))="inactive","Inactive",J75))) -> Active | L75: =Raw_Data_Copy!J75 -> จริง | M75: =Raw_Data_Copy!K75 -> 1) ทบทวนทะเบียนกฎหมายให้ครอบคลุมกฎกระทรวงฉบับนี้ โดยเฉพาะองค์กรที่ต้องใช้ผู้ชำนาญการภายนอกหรือบุคลากรภายในที่ต้องขึ้นเป็นผู้ชำนาญการตามกฎหมาย 2) ตรวจสอบคุณสมบัติ สถานะใบอนุญาต อายุใบอนุญาต การต่ออายุ และหลักฐานการพัฒนาความรู้ของผู้ชำนาญการที่องค์กรใช้ เพื่อป้องกันการใช้บุคคลที่ไม่มีสิทธิหรือใบอนุญาตหมดอายุ 3) ควบคุมเอกสารสำคัญ เช่น คำสั่งแต่งตั้ง/ว่าจ้าง สำเนาใบอนุญาต รายงานผลการปฏิบัติงาน หนังสือรับรอง ผลการประเมินอันตราย แผนงานด้านความปลอดภัย และหลักฐานการแจ้งต่ออธิบดี ให้พร้อมตรวจสอบ 4) ใช้กฎหมายฉบับนี้เชื่อมกับระบบ มรท.8001 ในเรื่องการคัดเลือกผู้มีความสามารถ การประเมินความสอดคล้องตามกฎหมาย การตรวจติดตามภายใน และการควบคุมผู้รับจ้าง/ที่ปรึกษาด้านความปลอดภัย 5) หากองค์กรมี จป. ระดับเทคนิค/เทคนิคขั้นสูง/วิชาชีพ ที่จะพัฒนาไปเป็นผู้ชำนาญการ ควรจัดทำแผนพัฒนาความสามารถและเส้นทางคุณวุฒิให้ชัดเจน เพื่อใช้ทั้งเชิง compliance และเชิงพัฒนาระบบความปลอดภัยขององค์กร | N75: =--(I75="Implemented") -> 1 | O75: =--(I75="Identified") -> 0 | P75: =--(I75="Evaluated") -> 0 | Q75: =--(K75="Active") -> 1 | R75: =--(K75="Inactive") -> 0 | S75: =--(K75="") -> 0 | T75: =--(AND(K75="Active",I75<>"Implemented")) -> 0 | U75: =--(E75="") -> 0 | V75: =--(M75="") -> 0 | W75: =--(OR(U75=1,S75=1,V75=1)) -> 0 | X75: =Raw_Data_Copy!G75 -> https://legal.labour.go.th/images/law/Safety2554/2567/Safety_14-11-67.pdf | Y75: =Raw_Data_Copy!D75 -> 0 | Z75: =Raw_Data_Copy!A75 -> กฎกระทรวง

Sheet Raw_Data_Copy
A1: Subject | B1: No | C1: Category | D1: Document ID / Reference No. | E1: Legal / Regulatory Title | F1: Date of Issue / Effective Date | G1: Legal Reference Link | H1: Key Legal & Regulatory Requirements | I1: Compliance Implementation Status | J1: (Y) Compliant / (N) Non-Compliant | K1: Implementation Guidance & Evidence Examples | L1: Legal Validity Status | M1: Approval status
A2: พระราชบัญญัติ | B2: 1 | C2: กฎหมายคุ้มครองแรงงาน | E2: พระราชบัญญัติคุ้มครองแรงงาน พ.ศ. 2541 และที่แก้ไขเพิ่มเติม | F2: 2/20/1998 | G2: https://legal.labour.go.th/images/law/Protection2541/2541_labour_protection.pdf | H2: พระราชบัญญัติฉบับนี้มีขึ้นเพื่อปรับปรุงกฎหมายแรงงานให้เหมาะสมกับสถานการณ์ในปัจจุบัน โดยยกเลิกประกาศเดิมที่ใช้มานานและไม่ทันต่อการเปลี่ยนแปลงของรูปแบบการจ้างงานและบริบททางเศรษฐกิจ–สังคม กฎหมายฉบับใหม่นี้มุ่งส่งเสริมความเป็นธรรมในการจ้างงาน เพิ่มประสิทธิภาพในการคุ้มครองแรงงาน และให้อำนาจเจ้าหน้าที่สามารถตรวจสอบสถานประกอบการได้อย่างเหมาะสม เพื่อให้แรงงานได้รับสิทธิตามกฎหมาย และนายจ้างได้รับประโยชน์จากแรงงานที่มีคุณภาพ ช่วยเสริมสร้างเสถียรภาพทางเศรษฐกิจในระยะยาวของประเทศ. | I2: Implemented | J2: จริง | K2: สื่อสารผ่าน e-smart/ idoc / ข้อบังคับการทำงาน | L2: Active | M2: 3
A3: พระราชบัญญัติ | B3: 2 | C3: กฎหมายพัฒนาฝีมือแรงงาน | E3: พระราชบัญญัติส่งเสริมการพัฒนาฝีมือแรงงาน พ.ศ. 2545 และที่แก้ไขเพิ่มเติม | F3: 9/22/2002 | G3: https://idev.dsd.go.th/~law/qr1/01%20%A1%AE%CB%C1%D2%C2%B7%D5%E8%E0%A1%D5%E8%C2%C7%A2%E9%CD%A7%A1%D1%BA%A1%D2%C3%BE%D1%B2%B9%D2%BD%D5%C1%D7%CD%E1%C3%A7%A7%D2%B9/%20%BE%C3%D0%C3%D2%AA%BA%D1%AD%AD%D1%B5%D4/1.%20%BE%C3%D0%C3%D2%AA%BA%D1%AD%AD%D1%B5%D4%CA%E8%A7%E0%CA%C3%D4%C1%A1%D2%C3%BE%D1%B2%B9%D2%BD%D5%C1%D7%CD%E1%C3%A7%A7%D2%B9%20%BE.%C8.2545%20%E1%C5%D0%B7%D5%E8%E1%A1%E9%E4%A2%E0%BE%D4%E8%C1%E0%B5%D4%C1.pdf | H3: พระราชบัญญัติส่งเสริมการพัฒนาฝีมือแรงงาน พ.ศ. 2545 ตราขึ้นเพื่อให้ครอบคลุมหรือเพียงพอต่อการส่งเสริมและพัฒนาฝีมือแรงงานในยุคปัจจุบัน ทั้งในด้านการพัฒนาทักษะ ความรู้ความสามารถ การรับรองมาตรฐานฝีมือแรงงาน และการสร้างความปลอดภัยในสถานประกอบกิจการ ภายหลังได้มีความจำเป็นต้องปรับปรุงกฎหมายให้เหมาะสมกับสถานการณ์ โดยส่งเสริมให้นายจ้างหรือสถานประกอบกิจการมีบทบาทสำคัญในการพัฒนาทักษะลูกจ้างให้เป็นระบบ และสามารถใช้ผลการประเมินความรู้ความสามารถเป็นหลักฐานในการประกอบอาชีพหรือรับสิทธิประโยชน์จากรัฐได้ เพื่อส่งเสริมให้แรงงานไทยมีทักษะสูงขึ้น สอดคล้องกับความต้องการของตลาดแรงงาน และยกระดับขีดความสามารถในการแข่งขันของประเทศ | I3: Implemented | J3: จริง | K3: สื่อสารผ่าน e-smart/ idoc / ขั้นตอนการปฏิบัติงานเกี่ยวกับพัฒนาฝีมือแรงงาน | L3: Active | M3: 3
A4: พระราชบัญญัติ | B4: 3 | C4: กฎหมายแรงงานสัมพันธ์ | E4: พระราชบัญญัติแรงงานสัมพันธ์ พ.ศ. 2518 | F4: 2/14/1975 | G4: https://legal.labour.go.th/images/law/Relation2518/labour_relation2518.pdf | H4: พระราชบัญญัตินี้ถูกประกาศใช้เนื่องจากประกาศของคณะปฏิวัติฉบับที่ 13 (16 มีนาคม 2517) เกี่ยวกับแรงงานสัมพันธ์ไม่เหมาะสมกับสภาพเศรษฐกิจและสังคมปัจจุบัน จึงมีการกำหนดหลักเกณฑ์ใหม่เกี่ยวกับการยื่นข้อเรียกร้องและการระงับข้อพิพาทแรงงานที่เหมาะสม โดยนายจ้างต้องจัดตั้งสหภาพนายจ้างและลูกจ้างต้องจัดตั้งสหภาพแรงงาน เพื่อคุ้มครองผลประโยชน์ด้านการจ้าง สวัสดิการ และส่งเสริมความสัมพันธ์ระหว่างนายจ้างกับลูกจ้าง รวมถึงให้ลูกจ้างจัดตั้งคณะกรรมการลูกจ้างเป็นองค์กรในการหารือกับนายจ้างเพื่อความเข้าใจและหาทางปรองดองในการทำงานร่วมกัน | I4: Implemented | J4: จริง | K4: สื่อสารผ่าน e-smart/ idoc | L4: Active | M4: 3
A5: พระราชบัญญัติ | B5: 4 | C5: กฎหมาย อื่น ๆ | E5: พระราชบัญญัติป้องกันและปราบปรามการค้ามนุษย์ พ.ศ. 2551 และฉบับที่แก้ไขเพิ่มเติม | F5: 12/30/2008 | G5: https://web.parliament.go.th/aseanrelated_law/files/file_20170817115531_0.pdf | H5: พระราชบัญญัตินี้ประกาศใช้เนื่องจากพระราชบัญญัติมาตรการในการป้องกันและปราบปรามการค้าหญิงและเด็ก พ.ศ. ๒๕๔๐ ยังไม่ครอบคลุมการกระทำเพื่อแสวงหาประโยชน์โดยมิชอบจากบุคคลที่มิได้จำกัดเฉพาะหญิงและเด็ก และรูปแบบการค้ามนุษย์ที่หลากหลายขึ้น ประกอบกับประเทศไทยได้ลงนามอนุสัญญาสหประชาชาติเพื่อต่อต้านอาชญากรรมข้ามชาติที่จัดตั้งในลักษณะองค์กร จึงสมควรกำหนดลักษณะความผิดให้ครอบคลุมการกระทำดังกล่าวเพื่อเพิ่มประสิทธิภาพในการป้องกันและปราบปรามการค้ามนุษย์ สอดคล้องกับพันธกรณีของอนุสัญญาฯ รวมถึงปรับปรุงการช่วยเหลือและคุ้มครองสวัสดิภาพผู้เสียหายให้เหมาะสม เพื่อประโยชน์สูงสุดของผู้เสียหาย | I5: Implemented | J5: จริง | K5: สื่อสารผ่าน e-smart/ idoc | L5: Active | M5: 3
A6: พระราชบัญญัติ | B6: 5 | C6: กฎหมายประกันสังคม | E6: พระราชบัญญัติประกันสังคม พ.ศ. 2533 และฉบับที่แก้ไขเพิ่มเติม | F6: 12/30/2008 | G6: https://www.mol.go.th/wp-content/uploads/sites/2/2021/02/2-%E0%B8%9E%E0%B8%A3%E0%B8%9A.%E0%B8%9B%E0%B8%A3%E0%B8%B0%E0%B8%81%E0%B8%B1%E0%B8%99%E0%B8%AA%E0%B8%B1%E0%B8%87%E0%B8%84%E0%B8%A1-%E0%B8%9E.%E0%B8%A8.-2533.pdf | H6: พระราชบัญญัติฉบับนี้จัดตั้งระบบประกันสังคมเพื่อให้ลูกจ้างได้รับความคุ้มครองด้านค่ารักษาพยาบาล ค่าชดเชยรายได้ ทุพพลภาพ เสียชีวิต คลอดบุตร และชราภาพ โดยจัดตั้งกองทุนประกันสังคมที่ได้รับเงินสมทบจากนายจ้าง ลูกจ้าง และรัฐ เพื่อบริหารจัดการให้ความช่วยเหลือผู้ประกันตนในกรณีที่ประสบเหตุจำเป็นต่าง ๆ โดยมีสำนักงานประกันสังคมเป็นหน่วยงานรับผิดชอบหลัก | I6: Implemented | J6: จริง | K6: สื่อสารผ่าน e-smart/ idoc | L6: Active | M6: 3
A7: พระราชบัญญัติ | B7: 6 | C7: กฎหมายประกันสังคม | E7: พระราชบัญญัติเงินทดแทน พ.ศ. 2537 และฉบับที่แก้ไขเพิ่มเติม | F7: 6/14/1994 | G7: https://www.sso.go.th/wpr/assets/upload/files_storage/sso_th/84244ea51a2464c0713a98ddd8cc0955.pdf | H7: พระราชบัญญัติฉบับนี้จัดตั้งระบบเงินทดแทนขึ้นเพื่อให้ความคุ้มครองแก่ลูกจ้างกรณีได้รับอันตราย ทุพพลภาพ หรือเสียชีวิตจากการทำงาน โดยนายจ้างต้องจ่ายเงินทดแทนตามอัตราที่กฎหมายกำหนด รวมถึงให้สำนักงานประกันสังคมเป็นผู้บริหารระบบเงินทดแทน เพื่อดูแลสิทธิของลูกจ้างในการได้รับค่ารักษาพยาบาล ค่าฟื้นฟูสมรรถภาพ ค่าทำศพ หรือค่าชดเชยรายได้ตามเงื่อนไขที่บัญญัติไว้ในกฎหมาย | I7: Implemented | J7: จริง | K7: สื่อสารผ่าน e-smart/ idoc | L7: Active | M7: 3
A8: พระราชกฤษฎีกา | B8: 7 | C8: กฎหมายคุ้มครองแรงงาน | E8: พระราชกฤษฎีกา กำหนดระยะเวลาเริ่มดำเนินการจัดเก็บเงินสะสมและเงินสมทบกองทุนสงเคราะห์ลูกจ้าง พ.ศ. 2567 | F8: 11/15/2024 | G8: https://legal.labour.go.th/images/law/Protection2541/2567/EWF_14-11-67.pdf | H8: พระราชกฤษฎีกาฉบับนี้มีขึ้นเพื่อรองรับการดำเนินการตามมาตรา 133 แห่งพระราชบัญญัติคุ้มครองแรงงาน พ.ศ. 2541 ซึ่งกำหนดให้มีการจัดเก็บเงินสะสมและเงินสมทบเข้ากองทุนสงเคราะห์ลูกจ้างในหมวด 13 โดยจะมีผลบังคับใช้เมื่อมีการประกาศเป็นพระราชกฤษฎีกาอย่างเป็นทางการ ดังนั้นจึงมีความจำเป็นต้องตราพระราชกฤษฎีกานี้เพื่อให้สามารถดำเนินการตามกฎหมายได้. | I8: Evaluated | J8: จริง | K8: สื่อสารผ่าน e-smart/ idoc | L8: Active | M8: 3
A9: กฎกระทรวง | B9: 8 | C9: กฎหมายคุ้มครองแรงงาน | D9: 68372 | E9: กฎกระทรวง กำหนดค่าล่วงเวลาและค่าตอบแทนการทำงานที่เกินวันละแปดชั่วโมง ในงานเฝ้าดูแลสถานที่หรือทรัพย์สินอันเป็นหน้าที่การทำงานปกติของลูกจ้าง พ.ศ. 2568 | F9: 4/24/2025 | G9: https://ratchakitcha.soc.go.th/documents/68372.pdf | H9: กฎกระทรวงฉบับนี้มีขึ้นเพื่อยกเลิกกฎกระทรวงเดิมที่ไม่เปิดโอกาสให้ลูกจ้างในงานที่ดูแลสถานที่หรือทรัพย์สินได้รับค่าล่วงเวลาและค่าทำงานในวันหยุด ทั้งที่ปฏิบัติงานตามคำสั่งนายจ้างอย่างต่อเนื่อง โดยพระราชบัญญัติคุ้มครองแรงงานได้ถูกแก้ไขเพิ่มเติมให้สอดคล้องกับสภาพการจ้างที่เปลี่ยนแปลงไปและให้ลูกจ้างกลุ่มนี้ได้รับสิทธิคุ้มครองเช่นเดียวกับลูกจ้างทั่วไป ดังนั้น จึงจำเป็นต้องออกกฎกระทรวงฉบับใหม่นี้เพื่อให้เป็นไปตามแนวทางของกฎหมายฉบับแก้ไขใหม่. | I9: Evaluated | J9: จริง | K9: สื่อสารผ่าน e-smart/ idoc | L9: Active | M9: 3
A10: กฎกระทรวง | B10: 9 | C10: กฎหมายคุ้มครองแรงงาน | E10: กฎกระทรวง กำหนดหลักเกณฑ์และวิธีการจัดการสงเคราะห์แก่ลูกจ้าง ในกรณีที่ลูกจ้างออกจากงานหรือตาย พ.ศ. 2567 | F10: 11/21/2025 | G10: https://legal.labour.go.th/images/law/Protection2541/2567/EWF2_14-11-67.pdf | H10: กฎกระทรวงฉบับนี้มีขึ้นเพื่อกำหนดหลักเกณฑ์และวิธีการสงเคราะห์ลูกจ้างที่นายจ้างไม่สามารถจ่ายเงินสงเคราะห์ได้ในกรณีที่ลูกจ้างออกจากงานหรือตาย ซึ่งตามมาตรา 130 วรรคสอง แห่งพระราชบัญญัติคุ้มครองแรงงาน พ.ศ. 2541 ระบุให้ลูกจ้างในกรณีดังกล่าวได้รับสิทธิในเงินสงเคราะห์จากกองทุนฯ แต่กฎหมายยังไม่ได้กำหนดหลักเกณฑ์อย่างชัดเจน จึงจำเป็นต้องออกกฎกระทรวงนี้เพื่อให้การสงเคราะห์เป็นไปอย่างมีหลักเกณฑ์และเกิดประโยชน์แก่ลูกจ้างหรือทายาทของลูกจ้าง. | I10: Implemented | J10: จริง | K10: สื่อสารผ่าน e-smart/ idoc | L10: Inactive | M10: 3
A11: กฎกระทรวง | B11: 10 | C11: กฎหมายคุ้มครองแรงงาน | E11: กฎกระทรวง กำหนดอัตราเงินสะสมและเงินสมทบกองทุนสงเคราะห์ลูกจ้าง พ.ศ. 2567 | F11: 11/22/2025 | G11: https://legal.labour.go.th/images/law/Protection2541/2567/EWF1_14-11-67.pdf | H11: กฎกระทรวงฉบับนี้มีขึ้นเพื่อกำหนดหลักเกณฑ์ให้ลูกจ้างที่เป็นสมาชิกกองทุนสงเคราะห์ลูกจ้าง และได้รับค่าจ้างจากนายจ้าง ต้องถูกหักเงินส่วนหนึ่งเข้ากองทุนทุกครั้งที่ได้รับค่าจ้าง โดยอัตราการหักต้องไม่เกินร้อยละห้าของค่าจ้างตามที่กำหนดในกฎกระทรวง ทั้งนี้เพื่อให้การดำเนินงานของกองทุนมีความต่อเนื่องและเป็นไปตามกฎหมาย จึงมีความจำเป็นต้องออกกฎกระทรวงนี้. | I11: Evaluated | J11: จริง | K11: สื่อสารผ่าน e-smart/ idoc | L11: Inactive | M11: 3
A12: กฎกระทรวง | B12: 11 | C12: กฎหมาย อื่น ๆ | E12: กฎกระทรวง กำหนดประเภทของสถานประกอบกิจการและการดำเนินการของสถานประกอบกิจการในการป้องกันและแก้ไขปัญหาการตั้งครรภ์ในวัยรุ่นแก่ลูกจ้างซึ่งเป็นวัยรุ่น พ.ศ. 2561 | F12: 11/16/2018 | G12: https://legal.labour.go.th/images/law/Protection2541/2561_21.PDF | H12: กฎกระทรวงฉบับนี้กำหนดให้สถานประกอบกิจการทุกประเภทต้องดำเนินการให้ข้อมูล ความรู้ และมาตรการเพื่อป้องกันและแก้ไขปัญหาการตั้งครรภ์ในวัยรุ่นแก่ลูกจ้างที่เป็นวัยรุ่นอย่างเหมาะสม ครอบคลุมด้านความรู้เรื่องการคุมกำเนิด การเลี้ยงดูบุตรหลังคลอด และโรคติดต่อทางเพศสัมพันธ์ โดยอาจจัดให้มีบริการให้คำปรึกษา หรือส่งต่อหน่วยบริการด้านสาธารณสุขหรือสวัสดิการที่เกี่ยวข้อง ทั้งนี้เพื่อให้ลูกจ้างวัยรุ่นได้รับความคุ้มครองและมีคุณภาพชีวิตที่เหมาะสมในการทำงาน | I12: Evaluated | J12: จริง | K12: สื่อสารผ่าน e-smart/ idoc | L12: Active | M12: 3
A13: กฎกระทรวง | B13: 12 | C13: กฎหมายคุ้มครองแรงงาน | E13: กฎกระทรวง ว่าด้วยการจัดสวัสดิการในสถานประกอบกิจการ พ.ศ. 2548 | F13: 3/29/2005 | G13: https://legal.labour.go.th/images/law/Protection2541/2541_17.pdf | H13: กฎกระทรวงฉบับนี้กำหนดให้สถานประกอบกิจการต้องจัดให้มีน้ำดื่มสะอาด ห้องน้ำ ห้องอาบน้ำ รวมถึงห้องส้วมที่เพียงพอ แยกชายหญิง และเหมาะสมกับลักษณะงานหรือคนพิการ และในสถานที่ทำงานต้องจัดให้มีห้องพยาบาลหรือบริการปฐมพยาบาลเบื้องต้น รวมถึงสถานพยาบาลหากลูกจ้างเจ็บป่วย ทั้งนี้เพื่อส่งเสริมสุขภาพและความเป็นอยู่ที่เหมาะสมของลูกจ้างในทุกสถานประกอบกิจการ | I13: Implemented | J13: จริง | K13: สื่อสารผ่าน e-smart/ idoc | L13: Active | M13: 3
A14: กฎกระทรวง | B14: 13 | C14: กฎหมายคุ้มครองแรงงาน | E14: กฎกระทรวง กำหนดอัตราน้ำหนักให้ลูกจ้างทำงานได้ พ.ศ. 2547 | F14: 4/23/2004 | G14: https://legal.labour.go.th/images/law/Protection2541/2541_15.pdf | H14: กฎกระทรวงฉบับนี้กำหนดน้ำหนักสูงสุดที่นายจ้างสามารถให้ลูกจ้างแบก หาม หาบ ทูน ลาก หรือเข็นของหนักได้อย่างปลอดภัย โดยจำกัดไม่ให้เกินอัตราที่เหมาะสมกับเพศและอายุของลูกจ้าง เช่น เด็กหญิงและเด็กชายอายุต่ำกว่า 18 ปี ห้ามแบกของเกิน 15–20 กิโลกรัม และในกรณีทั่วไปลูกจ้างหญิงห้ามทำงานแบกของเกิน 25 กิโลกรัม ส่วนลูกจ้างชายไม่เกิน 55 กิโลกรัม ทั้งนี้เพื่อป้องกันการบาดเจ็บและอันตรายจากการทำงาน และเพื่อให้สอดคล้องกับหลักการคุ้มครองแรงงานอย่างปลอดภัยและเหมาะสม | I14: Implemented | J14: จริง | K14: สื่อสารผ่าน e-smart/ idoc | L14: Active | M14: 3
A15: กฎกระทรวง | B15: 14 | C15: กฎหมายคุ้มครองแรงงาน | E15: กฎกระทรวง ฉบับที่ 2 (พ.ศ. 2541) ออกตามความในพระราชบัญญัติคุ้มครองแรงงาน พ.ศ. 2541 | F15: 8/19/1998 | G15: https://legal.labour.go.th/images/law/Protection2541/2541_2.pdf | H15: กฎกระทรวงฉบับนี้กำหนดให้นายจ้างต้องจำกัดเวลาทำงานปกติไม่เกินวันละแปดชั่วโมงสำหรับงานทุกประเภท และในกรณีของงานที่มีลักษณะเสี่ยงต่อสุขภาพหรือความปลอดภัย เช่น งานในที่อับอากาศ งานเกี่ยวกับสารเคมี งานที่ต้องใช้ความร้อนหรือเครื่องจักรอันตราย ฯลฯ นายจ้างต้องจัดมาตรการควบคุมความเสี่ยงตามมาตรฐานความปลอดภัยที่กฎกระทรวงกำหนด ไม่สามารถยืดหยุ่นหรือปรับปรุงให้ทำงานเกินเวลาได้ และต้องมีมาตรการป้องกันที่เข้มงวดเพื่อคุ้มครองลูกจ้างจากอันตรายในการทำงาน | I15: Implemented | J15: จริง | K15: สื่อสารผ่าน e-smart/ idoc | L15: Active | M15: 3
A16: กฎกระทรวง | B16: 15 | C16: กฎหมายคุ้มครองแรงงาน | E16: กฎกระทรวง ฉบับที่ 3 (พ.ศ. 2541) ออกตามความในพระราชบัญญัติคุ้มครองแรงงาน พ.ศ. 2541 | F16: 8/19/1998 | G16: https://legal.labour.go.th/images/law/Protection2541/2541_3.pdf | H16: กฎกระทรวงฉบับนี้กำหนดให้จำนวนชั่วโมงการทำงานล่วงเวลาและการทำงานในวันหยุดรวมกันในแต่ละสัปดาห์ต้องไม่เกิน 36 ชั่วโมง และในกรณีที่มีการทำงานในวันหยุด ชั่วโมงดังกล่าวต้องนับรวมเป็นชั่วโมงล่วงเวลาด้วย ทั้งนี้เพื่อควบคุมไม่ให้ลูกจ้างทำงานเกินความเหมาะสม และรักษาสิทธิของลูกจ้างในการพักผ่อนและสภาพการทำงานที่เป็นธรรมตามเจตนารมณ์ของพระราชบัญญัติคุ้มครองแรงงาน. | I16: Implemented | J16: จริง | K16: สื่อสารผ่าน e-smart/ idoc | L16: Active | M16: 3
A17: กฎกระทรวง | B17: 16 | C17: กฎหมายคุ้มครองแรงงาน | E17: กฎกระทรวง ฉบับที่ 4 (พ.ศ. 2541) ออกตามความในพระราชบัญญัติคุ้มครองแรงงาน พ.ศ. 2541 | F17: 8/19/1998 | G17: https://legal.labour.go.th/images/law/Protection2541/2541_4.pdf | H17: กฎกระทรวงฉบับนี้กำหนดให้นายจ้างสามารถให้ลูกจ้างทำงานในวันหยุดตามประเพณีได้ในบางกรณี เช่น งานในโรงแรม ร้านอาหาร สถานบันเทิง สถานพยาบาล หรือธุรกิจท่องเที่ยว รวมถึงงานในพื้นที่ห่างไกลหรือทุรกันดาร และงานขนส่งหรือติดต่อที่หากหยุดงานจะกระทบต่อการดำเนินงาน ทั้งนี้เพื่อให้กิจการที่มีลักษณะพิเศษสามารถดำเนินต่อเนื่องได้โดยไม่กระทบต่อบริการหรือความเสียหายของงานนั้น ๆ | I17: Implemented | J17: จริง | K17: สื่อสารผ่าน e-smart/ idoc | L17: Active | M17: 3
A18: กฎกระทรวง | B18: 17 | C18: กฎหมายคุ้มครองแรงงาน | E18: กฎกระทรวง ฉบับที่ 5 (พ.ศ. 2541) ออกตามความในพระราชบัญญัติคุ้มครองแรงงาน พ.ศ. 2541 | F18: 8/19/1998 | G18: https://legal.labour.go.th/images/law/Protection2541/2541_5.pdf | H18: กฎกระทรวงฉบับนี้กำหนดให้ลูกจ้างมีสิทธิเข้ารับการฝึกอบรมหรือฝึกหัดทางวิชาการเพื่อพัฒนาความรู้และเพิ่มประสิทธิภาพในการทำงาน โดยนายจ้างต้องแจ้งล่วงหน้าและไม่เรียกเก็บค่าใช้จ่ายใด ๆ ทั้งสิ้น รวมถึงต้องระบุหลักสูตรและระยะเวลาให้ชัดเจน และห้ามนำข้อมูลจากการอบรมไปใช้ในทางที่ไม่เกี่ยวข้องหรือให้ประโยชน์แก่ผู้อื่นที่ไม่ได้เข้าร่วมอบรม | I18: Implemented | J18: จริง | K18: สื่อสารผ่าน e-smart/ idoc | L18: Active | M18: 3
A19: กฎกระทรวง | B19: 18 | C19: กฎหมายคุ้มครองแรงงาน | E19: กฎกระทรวง ฉบับที่ 6 (พ.ศ. 2541) ออกตามความในพระราชบัญญัติคุ้มครองแรงงาน พ.ศ. 2541 | F19: 8/19/1998 | G19: https://legal.labour.go.th/images/law/Protection2541/2541_6.pdf | H19: กฎกระทรวงฉบับนี้ห้ามนายจ้างให้เด็กอายุต่ำกว่า 18 ปีทำงานบางประเภทที่อาจเป็นอันตราย เช่น งานเกี่ยวกับเครื่องจักร งานยกของหนัก งานในเรือเดินทะเล งานผลิตสุรา บุหรี่ หรือยาเสพติด และงานที่อาจกระทบต่อสุขภาพ ความปลอดภัย หรือศีลธรรมของเด็ก เพื่อคุ้มครองสวัสดิภาพและพัฒนาการที่เหมาะสมของเยาวชนในวัยทำงาน | I19: Implemented | J19: จริง | K19: สื่อสารผ่าน e-smart/ idoc | L19: Active | M19: 3
A20: กฎกระทรวง | B20: 19 | C20: กฎหมายคุ้มครองแรงงาน | E20: กฎกระทรวง ฉบับที่ 12 (พ.ศ. 2541) ออกตามความในพระราชบัญญัติคุ้มครองแรงงาน พ.ศ. 2541 | F20: 9/14/1998 | G20: https://legal.labour.go.th/images/law/Protection2541/2541_12.pdf | H20: กฎกระทรวงฉบับนี้ออกตามพระราชบัญญัติคุ้มครองแรงงาน พ.ศ. 2541 เพื่อกำหนดรายละเอียดเกี่ยวกับการทำงานในวันหยุดของลูกจ้างรายวัน รายสัปดาห์ หรือรายอื่นที่ไม่ใช่รายเดือน โดยมีเนื้อหาหลักคือ ให้นายจ้างสามารถให้ลูกจ้างทำงานในวันหยุดได้หากลูกจ้างยินยอม และต้องได้รับค่าจ้างเพิ่มตามที่กฎหมายกำหนด นอกจากนี้ยังระบุกรณีที่ลูกจ้างทำงานต่อเนื่องถึงวันหยุด โดยให้นับชั่วโมงการทำงานในวันหยุดรวมกับชั่วโมงปกติ และให้นับค่าจ้างในอัตราพิเศษตามช่วงเวลาที่เกินจากเวลาทำงานปกติ ทั้งนี้เพื่อให้การจ่ายค่าจ้างและการจัดสรรเวลาทำงานเป็นธรรมตามสิทธิที่ลูกจ้างพึงได้รับ. | I20: Implemented | J20: จริง | K20: สื่อสารผ่าน e-smart/ idoc | L20: Active | M20: 3
A21: กฎกระทรวง | B21: 20 | C21: กฎหมายคุ้มครองแรงงาน | E21: กฎกระทรวง ฉบับที่ 13 (พ.ศ. 2543) ออกตามความในพระราชบัญญัติคุ้มครองแรงงาน พ.ศ. 2541 | F21: 1/24/2000 | G21: https://legal.labour.go.th/images/law/Protection2541/2541_13.pdf | H21: กฎกระทรวงฉบับนี้กำหนดให้การหยุดงานกรณีพนักงานลาคลอด หรือลาป่วยที่เกี่ยวกับการคลอดบุตร ต้องไม่ถือเป็นการขาดงานหรือกระทบสิทธิของลูกจ้าง โดยให้นายจ้างและลูกจ้างตกลงกำหนดเวลาทำงานที่ยืดหยุ่นได้ตามความเหมาะสม แต่ไม่เกิน 8 ชั่วโมงต่อวัน และไม่เกิน 48 ชั่วโมงต่อสัปดาห์ ทั้งนี้ให้ยกเลิกกฎกระทรวง ฉบับที่ 7 (พ.ศ. 2541) เพื่อปรับปรุงให้เหมาะสมกับสถานการณ์แรงงานในปัจจุบัน โดยเน้นความยืดหยุ่นในการจัดเวลาทำงานที่คำนึงถึงความจำเป็นของลูกจ้าง และความเห็นชอบร่วมกันระหว่างลูกจ้างและนายจ้าง. | I21: Implemented | J21: จริง | K21: สื่อสารผ่าน e-smart/ idoc | L21: Active | M21: 3
A22: กฎกระทรวง | B22: 21 | C22: กฎหมายประกันสังคม | E22: กฎกระทรวงกำหนดอัตราเงินสมทบกองทุนประกันสังคม พ.ศ. 2565 | F22: 44652 | G22: https://www.sso.go.th/wpr/assets/upload/files_storage/sso_th/61b1cf134d15fcbbcf8f791d9b838367.pdf | H22: กฎกระทรวงฉบับนี้กำหนดอัตราเงินสมทบเข้ากองทุนประกันสังคม สำหรับกรณีประสบอันตราย เจ็บป่วย ทุพพลภาพ ตาย คลอดบุตร และกรณีสงเคราะห์บุตร รวมถึงกรณีชราภาพและว่างงาน โดยแบ่งภาระระหว่างนายจ้าง ลูกจ้าง และรัฐ เช่น การสมทบกรณีเจ็บป่วยและคลอดบุตรจะอยู่ที่ 0.5% ของค่าจ้าง ส่วนกรณีชราภาพและว่างงานจะอยู่ที่ 3.0% ตามบัญชีแนบท้าย เพื่อให้การบริหารกองทุนมีความยั่งยืนและเพียงพอรองรับสิทธิประโยชน์ของผู้ประกันตนอย่างต่อเนื่อง | I22: Implemented | J22: จริง | K22: สื่อสารผ่าน e-smart/ idoc | L22: Active | M22: 3
A23: กฎกระทรวง | B23: 22 | C23: กฎหมายประกันสังคม | E23: กฎกระทรวงค่าฟื้นฟูสมรรถภาพในการทำงานที่ให้นายจ้างจ่าย พ.ศ. 2563 | F23: 3/26/2020 | G23: https://www.sso.go.th/wpr/assets/upload/files_storage/sso_th/8742268c94cafccf89f30ddc50c83af5.pdf | H23: กฎกระทรวงฉบับนี้กำหนดให้นายจ้างเป็นผู้รับผิดชอบค่าใช้จ่ายในการฟื้นฟูสมรรถภาพของลูกจ้างที่ประสบอันตรายหรือเจ็บป่วยจากการทำงาน เช่น ค่าฝึกอาชีพ ค่าอุปกรณ์ทางการแพทย์ ค่าพาหนะ และค่าใช้จ่ายอื่นตามที่คณะกรรมการการแพทย์เห็นสมควร โดยมีเพดานค่าใช้จ่ายสูงสุดในแต่ละกรณี เพื่อให้ลูกจ้างสามารถกลับไปทำงานหรือประกอบอาชีพได้อย่างมีประสิทธิภาพและเหมาะสมกับสภาพร่างกาย | I23: Implemented | J23: จริง | K23: สื่อสารผ่าน e-smart/ idoc | L23: Active | M23: 3
A24: กฎกระทรวง | B24: 23 | C24: กฎหมายประกันสังคม | E24: กฎกระทรวง ค่ารักษาพยาบาลที่ให้นายจ้างจ่าย พ.ศ. 2563 | G24: https://www.sso.go.th/wpr/assets/upload/files_storage/sso_th/8e53d6555bb1dacfe7e1a420467424e5.pdf | H24: กฎกระทรวงฉบับนี้กำหนดให้ยกเลิกกฎกระทรวงค่ารักษาพยาบาลฉบับเดิม และให้ใช้อัตราใหม่ในกรณีลูกจ้างได้รับอันตรายจากการทำงาน โดยนายจ้างต้องรับผิดชอบค่ารักษาพยาบาลตามความจำเป็น ไม่เกินเพดานที่กำหนด เช่น ค่าห้อง ค่าอาหาร ค่ารักษาพยาบาลทั่วไป ค่ายา และค่าบริการพยาบาล ทั้งนี้รวมถึงกรณีที่ลูกจ้างเข้ารับการรักษาต่อเนื่องหรือมีเหตุพิเศษที่จำเป็นต้องใช้อุปกรณ์หรือบริการเพิ่มเติม โดยต้องได้รับความเห็นชอบจากคณะกรรมการการแพทย์ ทั้งหมดนี้เพื่อให้ลูกจ้างได้รับการรักษาอย่างเพียงพอและลดภาระจากการเจ็บป่วยที่เกี่ยวข้องกับการทำงาน | I24: Implemented | J24: จริง | K24: สื่อสารผ่าน e-smart/ idoc | L24: Active | M24: 3
A25: กฎกระทรวง | B25: 24 | C25: กฎหมายคุ้มครองแรงงาน | E25: กฎกระทรวง กำหนดอัตราค่าทำศพที่ให้นายจ้างจ่าย พ.ศ. 2565 | F25: 44749 | G25: https://www.sso.go.th/wpr/assets/upload/files_storage/sso_th/35959cbcd4d03cb4a672596e54f9a9f8.pdf | H25: กฎกระทรวงฉบับนี้กำหนดให้นายจ้างจ่ายค่าทำศพให้แก่ผู้จัดการศพของลูกจ้างที่เสียชีวิตจากการทำงานหรือในขณะปฏิบัติงาน โดยให้อัตราการจ่ายเป็นไปตามที่กระทรวงกำหนดในแต่ละช่วงเวลา ทั้งนี้ประกาศฉบับใหม่นี้มีผลยกเลิกกฎกระทรวงฉบับเก่าปี พ.ศ. 2563 และให้ใช้บังคับกับกรณีที่ลูกจ้างเสียชีวิตตั้งแต่วันที่ 9 ธันวาคม 2564 เป็นต้นไป เพื่อให้สอดคล้องกับภาระค่าครองชีพและสภาพเศรษฐกิจในปัจจุบัน | I25: Implemented | J25: จริง | K25: สื่อสารผ่าน e-smart/ idoc | L25: Active | M25: 3
A26: กฎกระทรวง | B26: 25 | C26: กฎหมายคุ้มครองแรงงาน | D26: 142482 | E26: กฎกระทรวง กำหนดหลักเกณฑ์และอัตราการได้รับประโยชน์ทดแทนในการว่างงาน พ.ศ. 2547 | F26: 6/30/2022 | G26: https://ratchakitcha.soc.go.th/documents/142482.pdf | H26: กฎกระทรวงฉบับนี้กำหนดหลักเกณฑ์และอัตราที่ผู้ประกันตนจะได้รับเงินทดแทนในกรณีว่างงาน โดยมีสิทธิตามมาตรา 33 และ 39 ของพระราชบัญญัติประกันสังคม ได้แก่ ได้รับเงินชดเชยร้อยละ 50 ของค่าจ้างรายวัน ครั้งหนึ่งไม่เกิน 180 วันต่อปี หรือร้อยละ 30 ในกรณีลาออกหรือสิ้นสุดสัญญาจ้าง ครั้งหนึ่งไม่เกิน 90 วันต่อปี ทั้งนี้หากไม่ได้ทำงานอีกภายในช่วงเวลากำหนดยังสามารถขอต่อสิทธิได้ในปีถัดไป ผู้ว่างงานต้องรายงานตัวตามที่กำหนดและต้องไม่ได้มีงานทำหรือมีรายได้จากแหล่งอื่นจึงจะได้รับเงินประโยชน์ทดแทน | I26: Implemented | J26: จริง | K26: สื่อสารผ่าน e-smart/ idoc | L26: Active | M26: 3
A27: กฎกระทรวง | B27: 26 | C27: กฎหมายประกันสังคม | D27: 2096789 | E27: กฎกระทรวง การได้รับประโยชน์ทดแทนในการขาดรายได้กรณีเหตุสุดวิสัย พ.ศ. 2560 | F27: 1/17/2017 | G27: https://ratchakitcha.soc.go.th/documents/2096789.pdf | H27: กฎกระทรวงฉบับนี้กำหนดให้ผู้ประกันตนสามารถขอรับเงินทดแทนรายได้ในกรณีเหตุสุดวิสัย เช่น โรคระบาด อัคคีภัย หรือภัยพิบัติอื่นที่อยู่นอกเหนือการควบคุม ทำให้ไม่สามารถไปทำงานได้ตามปกติ โดยมีเงื่อนไขว่าต้องไม่ได้รับค่าจ้างจากนายจ้างในช่วงเวลานั้น และนายจ้าง และ/หรือหน่วยงานราชการต้องออกหนังสือรับรองเหตุสุดวิสัย ผู้ประกันตนสามารถยื่นคำร้องขอรับสิทธิได้ตามแบบที่กำหนดเพื่อรับเงินชดเชยในช่วงเวลาที่ขาดรายได้ | I27: Implemented | J27: จริง | K27: e-smart / I-Document | L27: Active | M27: 3
A28: กฎกระทรวง | B28: 27 | C28: กฎหมายประกันสังคม | D28: 54513 | E28: กฎกระทรวง การจ่ายประโยชน์ทดแทนในกรณีสงเคราะห์บุตร (ฉบับที่ 3) พ.ศ. 2567 | F28: 12/26/2024 | G28: https://ratchakitcha.soc.go.th/documents/54513.pdf | H28: กฎกระทรวงฉบับนี้แก้ไขเพิ่มเติมอัตราการจ่ายเงินสงเคราะห์บุตรให้แก่ผู้ประกันตน โดยกำหนดให้ได้รับเงินเดือนละ 1,000 บาท ต่อบุตรหนึ่งคน ซึ่งเป็นการแก้ไขจากฉบับเดิมเพื่อให้สอดคล้องกับค่าครองชีพที่เพิ่มขึ้น และสนับสนุนภาระค่าใช้จ่ายในการเลี้ยงดูบุตรของผู้ประกันตน | I28: Implemented | J28: จริง | K28: สื่อสารผ่าน e-smart/ idoc | L28: Active | M28: 3
A29: กฎกระทรวง | B29: 28 | C29: กฎหมายประกันสังคม | D29: 62636 | E29: ประกาศสำนักงานประกันสังคม เรื่อง กำหนดผลประโยชน์บำเน็จเงินชราภาพของผู้ประกันตนตามมาตรา 33 และมาตรา 39 | F29: 2/24/2022 | G29: https://ratchakitcha.soc.go.th/documents/62636.pdf | H29: ประกาศนี้กำหนดอัตราและวิธีการจ่ายเงินบำเน็จเงินชราภาพให้แก่ผู้ประกันตนที่เข้าเงื่อนไขตามกฎหมาย โดยให้นำเงินสมทบของผู้ประกันตนมาพิจารณาเป็นหลักในการคำนวณผลตอบแทน ทั้งนี้เพื่อความเหมาะสมกับสภาวะเศรษฐกิจและค่าใช้จ่ายในการดำรงชีพ รวมถึงเปิดโอกาสให้สำนักงานประกันสังคมสามารถปรับอัตราตามความจำเป็นโดยประกาศเพิ่มเติมได้ | I29: Implemented | J29: จริง | K29: สื่อสารผ่าน e-smart/ idoc | L29: Active | M29: 3
A30: กฎกระทรวง | B30: 29 | C30: กฎหมายประกันสังคม | E30: ประกาศกระทรวงแรงงาน เรื่อง หลักเกณณ์และวิธีการเรียกหรือรับหลักประกันการทำงานหรือหลักประกันความเสียหายในการทำงานจากลูกจ้าง พ.ศ. 2541 | F30: 39545 | G30: https://legal.labour.go.th/images/law/Protection2541/law10072551_1.pdf | H30: ประกาศฉบับนี้ออกตามพระราชบัญญัติคุ้มครองแรงงาน พ.ศ. 2541 เพื่อกำหนดให้สถานประกอบกิจการจัดให้มีการฝึกอบรมก่อนเริ่มงาน สำหรับงานที่อาจมีอันตรายหรือมีความเสี่ยง เช่น งานเกี่ยวกับไฟฟ้า เครื่องจักร หรือสารเคมี โดยเน้นให้ลูกจ้างได้รับความรู้ ความเข้าใจเกี่ยวกับความปลอดภัย วิธีปฏิบัติงาน การใช้อุปกรณ์ และมาตรการป้องกันอุบัติเหตุอย่างเหมาะสม นายจ้างต้องจัดฝึกอบรมด้วยวิธีการที่เข้าใจง่าย สื่อสารได้ผล และจัดทำบันทึกหลักฐานไว้เพื่อการตรวจสอบ ทั้งนี้เพื่อส่งเสริมสภาพการทำงานที่ปลอดภัย ลดอุบัติเหตุ และสร้างวัฒนธรรมความปลอดภัยในที่ทำงาน. | I30: Implemented | J30: จริง | K30: สื่อสารผ่าน e-smart/ idoc | L30: Active | M30: 3
